Workbook
Name Extension: DATA!$F$4:$F$7
Name Instruction: DATA!$D$4:$D$7
Name Production: DATA!$G$4:$G$7
Name Rank: DATA!$C$4:$C$7
Name Rank_Link: DATA!$B$4
Name Research: DATA!$E$4:$E$7
Name SubRank: DATA!$K$2:$K$7
Name SubRank_Link: DATA!$I$3

Sheet Faculty
A7: TEACHING EFFICIENCY RATING (TER) SCALE FORM
A9: Instructor: | C9: =TI!DC6 -> , | L9: Rating Period: | O9: =Entry!D7 -> 0
A10: College: | C10: =Entry!D19 -> 0 | L10: Department: | O10: =Entry!D20 -> 0
A12: I. PERFORMANCE 70% | H12: RATING | K12: RATING | O12: RATING | S12: POINT
K13: EQUIVALENT | O13: PERCENTAGE | S13: SCORE
A14: 1. Instruction (55%)
A15: a.) | B15: Student as Rater | H15: =TI!DJ36 -> #DIV/0! | K15: =H15*0.1 -> #DIV/0! | O15: 0.2 | S15: =K15*0.2 -> #DIV/0!
A16: b.) | B16: Peer as Rater | H16: =TI!MO36 -> #DIV/0! | K16: =H16*0.1 -> #DIV/0! | O16: 0.1 | S16: =K16*0.1 -> #DIV/0!
A17: c.) | B17: Dean as Rater | H17: =TI!U69 -> 0 | K17: =H17*0.1 -> 0 | O17: 0.15 | S17: =K17*0.15 -> 0
A18: d.) | B18: Self as Rater | H18: =TI!I69 -> 0 | K18: =H18*0.1 -> 0 | O18: 0.1 | S18: =K18*0.1 -> 0
A20: 2. Research | O20: 0.05
A21: 3. Extension Service | O21: 0.05
A22: 4. Productivity | O22: 0.05
A24: II. BEHAVIOR: 30%
A26: 1. Courtesy | K26: 10 | O26: 0.075 | S26: =K26*0.075 -> 0.75
A27: 2. Human Relations | K27: 10 | O27: 0.075 | S27: =K27*0.075 -> 0.75
A28: 3. Punctuality and Attendance | K28: 8 | O28: 0.075 | S28: =K28*0.075 -> 0.6
A29: 4, Initiative | K29: 10 | O29: 0.075 | S29: =K29*0.075 -> 0.75
A30: 5. Leadership (for Supervisors only) | O30: 0.05
A31: 6. Stress Tolerance (for Supervisors only) | O31: 0.05
A33: For full time Instructor - Items 1-4 onlyn at 7.5% per item
A34: For Supervisors - Item 1-6 at 5% per item
A36: PLUS FACTOR (not to exceed one (1) credit point)
K37: Overall Point Score | S37: =SUM(S15:T36) -> #DIV/0!
K38: Equivalent Numerical Rating | S38: =S37 -> #DIV/0!
K39: Equivalent Adjective Rating | S39: VS
A40: Descriptive Equivalent of Numerical Ratings:
C42: 9.3 & Above - Outstanding (O) | M42: DISCUSSED RATING WITH:
C43: 7.5 - 9.2 - Very Satisfactory (VS)
C44: 5.0 - 7.4 - Satisfactory (S) | M44: =TI!DC6 -> ,
C45: 3.0 - 4.9 - Unsatisfactory (US) | M45: Signature of Ratee/Date
C46: 2.0 - 2.9 - Poor (P)
A48: EMPLOYEE'S COMMENTS/REMARKS:
A49: ________________________________________ | M49: =Entry!D23 -> DANIEL E. MALIGAT, JR., DIT
A50: ________________________________________ | M50: Signature of Rater/Date
A51: ________________________________________
A52: RATER'S COMMENTS/REMARKS
A53: ________________________________________ | L53: DOLORES C. VOLANTE, Ed.D
A54: ________________________________________ | L54: Signature of Rater's Supervisor/Date
A55: ________________________________________
...

Sheet Entry
B1: Republic of the Philippines
A2: Engr. JAMIN E. SANTIAGO | B2: CAMARINES NORTE STATE COLLEGE
A3: 38873 | B3: Daet, Camarines Norte
A4: version 4
B7: RATING PERIOD
B12: SURNAME
B13: FIRST NAME
B14: MI
B16: PRESENT RANK
B18: SUB-RANK
B19: COLLEGE UNIT
B20: DEPARTMENT
B23: SUPERVISOR | D23: DANIEL E. MALIGAT, JR., DIT
B24: DESIGNATION | D24: DEAN
B31: Notes: | D31: There must be at least 5 peers.
D32: Perfect scores (100) for self, peer, and supervisor must be justified.

Sheet TI
B1: Republic of the Philippines
B2: CAMARINES NORTE STATE COLLEGE
B3: Daet, Camarines Norte
B5: TEACHING EFFECTIVENESS RATING
B6: Name of Faculty: | DC6: =Entry!D12 & ", " &Entry!D13 & " " &Entry!D14 -> , | MB6: Rating Period: | MG6: =Entry!D7 -> 0
B8: A. STUDENT AS RATER | DJ8: =AE43 -> 0.25 | MC8: B. PEER AS RATER | MO8: =AG43 -> 0.25
C9: Ave. | D9: Rank | DC9: 3 | MD9: Ave. | ME9: Rank | MG9: Peer No.
D10: Group | E10: All | F10: 1 | G10: 2 | H10: 3 | I10: 4 | J10: 5 | K10: 6 | L10: 7 | M10: 8 | N10: 9 | O10: 10 | P10: 11 | Q10: 12 | R10: 13 | S10: 14 | T10: 15 | U10: 16 | V10: 17 | W10: 18 | X10: 19 | Y10: 20 | Z10: 21 | AA10: 22 | AB10: 23 | AC10: 24 | AD10: 25 | AE10: 26 | AF10: 27 | AG10: 28 | AH10: 29 | AI10: 30 | AJ10: 31 | AK10: 32 | AL10: 33 | AM10: 34 | AN10: 35 | AO10: 36 | AP10: 37 | AQ10: 38 | AR10: 39 | AS10: 40 | AT10: 41 | AU10: 42 | AV10: 43 | AW10: 44 | AX10: 45 | AY10: 46 | AZ10: 47 | BA10: 48 | BB10: 49 | BC10: 50 | BD10: 51 | BE10: 52 | BF10: 53 | BG10: 54 | BH10: 55 | BI10: 56 | BJ10: 57 | BK10: 58 | BL10: 59 | BM10: 60 | BN10: 61 | BO10: 62 | BP10: 63 | BQ10: 64 | BR10: 65 | BS10: 66 | BT10: 67 | BU10: 68 | BV10: 69 | BW10: 70 | BX10: 71 | BY10: 72 | BZ10: 73 | CA10: 74 | CB10: 75 | CC10: 76 | CD10: 77 | CE10: 78 | CF10: 79 | CG10: 80 | CH10: 81 | CI10: 82 | CJ10: 83 | CK10: 84 | CL10: 85 | CM10: 86 | CN10: 87 | CO10: 88 | CP10: 89 | CQ10: 90 | CR10: 91 | CS10: 92 | CT10: 93 | CU10: 94 | CV10: 95 | CW10: 96 | CX10: 97 | CY10: 98 | CZ10: 99 | DA10: 100 | DB10: 101 | DC10: 102 | DD10: 103 | DE10: 104 | DF10: 105 | DG10: 106 | DH10: 107 | DI10: 108 | DJ10: 109 | DK10: 110 | DL10: 111 | DM10: 112 | DN10: 113 | DO10: 114 | DP10: 115 | DQ10: 116 | DR10: 117 | DS10: 118 | DT10: 119 | DU10: 120 | DV10: 121 | DW10: 122 | DX10: 123 | DY10: 124 | DZ10: 125 | EA10: 126 | EB10: 127 | EC10: 128 | ED10: 129 | EE10: 130 | EF10: 131 | EG10: 132 | EH10: 133 | EI10: 134 | EJ10: 135 | EK10: 136 | EL10: 137 | EM10: 138 | EN10: 139 | EO10: 140 | EP10: 141 | EQ10: 142 | ER10: 143 | ES10: 144 | ET10: 145 | EU10: 146 | EV10: 147 | EW10: 148 | EX10: 149 | EY10: 150 | EZ10: 151 | FA10: 152 | FB10: 153 | FC10: 154 | FD10: 155 | FE10: 156 | FF10: 157 | FG10: 158 | FH10: 159 | FI10: 160 | FJ10: 161 | FK10: 162 | FL10: 163 | FM10: 164 | FN10: 165 | FO10: 166 | FP10: 167 | FQ10: 168 | FR10: 169 | FS10: 170 | FT10: 171 | FU10: 172 | FV10: 173 | FW10: 174 | FX10: 175 | FY10: 176 | FZ10: 177 | GA10: 178 | GB10: 179 | GC10: 180 | GD10: 181 | GE10: 182 | GF10: 183 | GG10: 184 | GH10: 185 | GI10: 186 | GJ10: 187 | GK10: 188 | GL10: 189 | GM10: 190 | GN10: 191 | GO10: 192 | GP10: 193 | GQ10: 194 | GR10: 195 | GS10: 196 | GT10: 197 | GU10: 198 | GV10: 199 | GW10: 200 | GX10: 201 | GY10: 202 | GZ10: 203 | HA10: 204 | HB10: 205 | HC10: 206 | HD10: 207 | HE10: 208 | HF10: 209 | HG10: 210 | HH10: 211 | HI10: 212 | HJ10: 213 | HK10: 214 | HL10: 215 | HM10: 216 | HN10: 217 | HO10: 218 | HP10: 219 | HQ10: 220 | HR10: 221 | HS10: 222 | HT10: 223 | HU10: 224 | HV10: 225 | HW10: 226 | HX10: 227 | HY10: 228 | HZ10: 229 | IA10: 230 | IB10: 231 | ME10: Group | MF10: All | MG10: 1 | MH10: 2 | MI10: 3 | MJ10: 4 | MK10: 5 | ML10: 6 | MM10: 7 | MN10: 8 | MO10: 9 | MP10: 10 | MQ10: 11 | MR10: 12 | MS10: 13 | MT10: 14
B11: I. Commitment | DH11: =AI44 -> 0.25 | DJ11: =SUM(C12:C16) -> #DIV/0! | MC11: I. Commitment | MM11: =AI44 -> 0.25 | MO11: =SUM(MD12:MD16) -> #DIV/0! | MP11: =AVERAGE(MF12:MF16) -> #DIV/0!
C12: =AVERAGE(F12:IM12) -> #DIV/0! | D12: =RANK(C12,$C$12:$C$16) -> #DIV/0! | E12: =RANK(C12,$C$12:$C$34) -> #DIV/0! | MC12: 1 | MD12: =AVERAGE(MG12:MU12) -> #DIV/0! | ME12: =RANK(MD12,$MD$12:$MD$16) -> #DIV/0! | MF12: =RANK(MD12,$MD$12:$MD$34) -> #DIV/0!
C13: =AVERAGE(F13:IM13) -> #DIV/0! | D13: =RANK(C13,$C$12:$C$16) -> #DIV/0! | E13: =RANK(C13,$C$12:$C$34) -> #DIV/0! | MC13: 2 | MD13: =AVERAGE(MG13:MU13) -> #DIV/0! | ME13: =RANK(MD13,$MD$12:$MD$16) -> #DIV/0! | MF13: =RANK(MD13,$MD$12:$MD$34) -> #DIV/0!
C14: =AVERAGE(F14:IM14) -> #DIV/0! | D14: =RANK(C14,$C$12:$C$16) -> #DIV/0! | E14: =RANK(C14,$C$12:$C$34) -> #DIV/0! | MC14: 3 | MD14: =AVERAGE(MG14:MU14) -> #DIV/0! | ME14: =RANK(MD14,$MD$12:$MD$16) -> #DIV/0! | MF14: =RANK(MD14,$MD$12:$MD$34) -> #DIV/0!
C15: =AVERAGE(F15:IM15) -> #DIV/0! | D15: =RANK(C15,$C$12:$C$16) -> #DIV/0! | E15: =RANK(C15,$C$12:$C$34) -> #DIV/0! | MC15: 4 | MD15: =AVERAGE(MG15:MU15) -> #DIV/0! | ME15: =RANK(MD15,$MD$12:$MD$16) -> #DIV/0! | MF15: =RANK(MD15,$MD$12:$MD$34) -> #DIV/0!
C16: =AVERAGE(F16:IM16) -> #DIV/0! | D16: =RANK(C16,$C$12:$C$16) -> #DIV/0! | E16: =RANK(C16,$C$12:$C$34) -> #DIV/0! | MC16: 5 | MD16: =AVERAGE(MG16:MU16) -> #DIV/0! | ME16: =RANK(MD16,$MD$12:$MD$16) -> #DIV/0! | MF16: =RANK(MD16,$MD$12:$MD$34) -> #DIV/0!
B17: 5 | DH17: =AI50 -> 0.25 | DJ17: =SUM(C18:C22) -> #DIV/0! | MC17: II. Knowledge of Subject | MM17: =AI50 -> 0.25 | MN17: =AVERAGE(MD18:MD22) -> #DIV/0! | MO17: =SUM(MD18:MD22) -> #DIV/0! | MP17: =AVERAGE(MF18:MF22) -> #DIV/0!
B18: 1 | C18: =AVERAGE(F18:IM18) -> #DIV/0! | D18: =RANK(C18,$C$18:$C$22) -> #DIV/0! | E18: =RANK(C18,$C$12:$C$34) -> #DIV/0! | MC18: 1 | MD18: =AVERAGE(MG18:MU18) -> #DIV/0! | ME18: =RANK(MD18,$MD$18:$MD$22) -> #DIV/0! | MF18: =RANK(MD18,$MD$12:$MD$34) -> #DIV/0!
B19: 2 | C19: =AVERAGE(F19:IM19) -> #DIV/0! | D19: =RANK(C19,$C$18:$C$22) -> #DIV/0! | E19: =RANK(C19,$C$12:$C$34) -> #DIV/0! | MC19: 2 | MD19: =AVERAGE(MG19:MU19) -> #DIV/0! | ME19: =RANK(MD19,$MD$18:$MD$22) -> #DIV/0! | MF19: =RANK(MD19,$MD$12:$MD$34) -> #DIV/0!
B20: 3 | C20: =AVERAGE(F20:IM20) -> #DIV/0! | D20: =RANK(C20,$C$18:$C$22) -> #DIV/0! | E20: =RANK(C20,$C$12:$C$34) -> #DIV/0! | MC20: 3 | MD20: =AVERAGE(MG20:MU20) -> #DIV/0! | ME20: =RANK(MD20,$MD$18:$MD$22) -> #DIV/0! | MF20: =RANK(MD20,$MD$12:$MD$34) -> #DIV/0!
B21: 4 | C21: =AVERAGE(F21:IM21) -> #DIV/0! | D21: =RANK(C21,$C$18:$C$22) -> #DIV/0! | E21: =RANK(C21,$C$12:$C$34) -> #DIV/0! | MC21: 4 | MD21: =AVERAGE(MG21:MU21) -> #DIV/0! | ME21: =RANK(MD21,$MD$18:$MD$22) -> #DIV/0! | MF21: =RANK(MD21,$MD$12:$MD$34) -> #DIV/0!
B22: 5 | C22: =AVERAGE(F22:IM22) -> #DIV/0! | D22: =RANK(C22,$C$18:$C$22) -> #DIV/0! | E22: =RANK(C22,$C$12:$C$34) -> #DIV/0! | MC22: 5 | MD22: =AVERAGE(MG22:MU22) -> #DIV/0! | ME22: =RANK(MD22,$MD$18:$MD$22) -> #DIV/0! | MF22: =RANK(MD22,$MD$12:$MD$34) -> #DIV/0!
B23: \ | DH23: =AI56 -> 0.25 | DJ23: =SUM(C24:C28) -> #DIV/0! | MC23: III. Teaching for Independent Learning | MM23: =AI56 -> 0.25 | MN23: =AVERAGE(MD24:MD28) -> #DIV/0! | MO23: =SUM(MD24:MD28) -> #DIV/0! | MP23: =AVERAGE(MF24:MF28) -> #DIV/0!
B24: 1 | C24: =AVERAGE(F24:IM24) -> #DIV/0! | D24: =RANK(C24,$C$24:$C$28) -> #DIV/0! | E24: =RANK(C24,$C$12:$C$34) -> #DIV/0! | MC24: 1 | MD24: =AVERAGE(MG24:MU24) -> #DIV/0! | ME24: =RANK(MD24,$MD$24:$MD$28) -> #DIV/0! | MF24: =RANK(MD24,$MD$12:$MD$34) -> #DIV/0!
B25: 2 | C25: =AVERAGE(F25:IM25) -> #DIV/0! | D25: =RANK(C25,$C$24:$C$28) -> #DIV/0! | E25: =RANK(C25,$C$12:$C$34) -> #DIV/0! | MC25: 2 | MD25: =AVERAGE(MG25:MU25) -> #DIV/0! | ME25: =RANK(MD25,$MD$24:$MD$28) -> #DIV/0! | MF25: =RANK(MD25,$MD$12:$MD$34) -> #DIV/0!
B26: 3 | C26: =AVERAGE(F26:IM26) -> #DIV/0! | D26: =RANK(C26,$C$24:$C$28) -> #DIV/0! | E26: =RANK(C26,$C$12:$C$34) -> #DIV/0! | MC26: 3 | MD26: =AVERAGE(MG26:MU26) -> #DIV/0! | ME26: =RANK(MD26,$MD$24:$MD$28) -> #DIV/0! | MF26: =RANK(MD26,$MD$12:$MD$34) -> #DIV/0!
B27: 4 | C27: =AVERAGE(F27:IM27) -> #DIV/0! | D27: =RANK(C27,$C$24:$C$28) -> #DIV/0! | E27: =RANK(C27,$C$12:$C$34) -> #DIV/0! | MC27: 4 | MD27: =AVERAGE(MG27:MU27) -> #DIV/0! | ME27: =RANK(MD27,$MD$24:$MD$28) -> #DIV/0! | MF27: =RANK(MD27,$MD$12:$MD$34) -> #DIV/0!
B28: 5 | C28: =AVERAGE(F28:IM28) -> #DIV/0! | D28: =RANK(C28,$C$24:$C$28) -> #DIV/0! | E28: =RANK(C28,$C$12:$C$34) -> #DIV/0! | MC28: 5 | MD28: =AVERAGE(MG28:MU28) -> #DIV/0! | ME28: =RANK(MD28,$MD$24:$MD$28) -> #DIV/0! | MF28: =RANK(MD28,$MD$12:$MD$34) -> #DIV/0!
DH29: =AI62 -> 0.25 | DJ29: =SUM(C30:C34) -> #DIV/0! | MC29: IV. Management of Learning | MM29: =AI62 -> 0.25 | MN29: =AVERAGE(MD30:MD34) -> #DIV/0! | MO29: =SUM(MD30:MD34) -> #DIV/0! | MP29: =AVERAGE(MF30:MF34) -> #DIV/0!
B30: 1 | C30: =AVERAGE(F30:IM30) -> #DIV/0! | D30: =RANK(C30,$C$30:$C$34) -> #DIV/0! | E30: =RANK(C30,$C$12:$C$34) -> #DIV/0! | MC30: 1 | MD30: =AVERAGE(MG30:MU30) -> #DIV/0! | ME30: =RANK(MD30,$MD$30:$MD$34) -> #DIV/0! | MF30: =RANK(MD30,$MD$12:$MD$34) -> #DIV/0!
B31: 2 | C31: =AVERAGE(F31:IM31) -> #DIV/0! | D31: =RANK(C31,$C$30:$C$34) -> #DIV/0! | E31: =RANK(C31,$C$12:$C$34) -> #DIV/0! | MC31: 2 | MD31: =AVERAGE(MG31:MU31) -> #DIV/0! | ME31: =RANK(MD31,$MD$30:$MD$34) -> #DIV/0! | MF31: =RANK(MD31,$MD$12:$MD$34) -> #DIV/0!
B32: 3 | C32: =AVERAGE(F32:IM32) -> #DIV/0! | D32: =RANK(C32,$C$30:$C$34) -> #DIV/0! | E32: =RANK(C32,$C$12:$C$34) -> #DIV/0! | MC32: 3 | MD32: =AVERAGE(MG32:MU32) -> #DIV/0! | ME32: =RANK(MD32,$MD$30:$MD$34) -> #DIV/0! | MF32: =RANK(MD32,$MD$12:$MD$34) -> #DIV/0!
B33: 4 | C33: =AVERAGE(F33:IM33) -> #DIV/0! | D33: =RANK(C33,$C$30:$C$34) -> #DIV/0! | E33: =RANK(C33,$C$12:$C$34) -> #DIV/0! | MC33: 4 | MD33: =AVERAGE(MG33:MU33) -> #DIV/0! | ME33: =RANK(MD33,$MD$30:$MD$34) -> #DIV/0! | MF33: =RANK(MD33,$MD$12:$MD$34) -> #DIV/0!
B34: 5 | C34: =AVERAGE(F34:IM34) -> #DIV/0! | D34: =RANK(C34,$C$30:$C$34) -> #DIV/0! | E34: =RANK(C34,$C$12:$C$34) -> #DIV/0! | MC34: 5 | MD34: =AVERAGE(MG34:MU34) -> #DIV/0! | ME34: =RANK(MD34,$MD$30:$MD$34) -> #DIV/0! | MF34: =RANK(MD34,$MD$12:$MD$34) -> #DIV/0!
B35: =STDEVP(DC35:DZ35) -> 0 | E35: Total | F35: =SUM(F12:F16)+SUM(F18:F22)+SUM(F24:F28)+SUM(F30:F34) -> 0 | G35: =SUM(G12:G16)+SUM(G18:G22)+SUM(G24:G28)+SUM(G30:G34) -> 0 | H35: =SUM(H12:H16)+SUM(H18:H22)+SUM(H24:H28)+SUM(H30:H34) -> 0 | I35: =SUM(I12:I16)+SUM(I18:I22)+SUM(I24:I28)+SUM(I30:I34) -> 0 | J35: =SUM(J12:J16)+SUM(J18:J22)+SUM(J24:J28)+SUM(J30:J34) -> 0 | K35: =SUM(K12:K16)+SUM(K18:K22)+SUM(K24:K28)+SUM(K30:K34) -> 0 | L35: =SUM(L12:L16)+SUM(L18:L22)+SUM(L24:L28)+SUM(L30:L34) -> 0 | M35: =SUM(M12:M16)+SUM(M18:M22)+SUM(M24:M28)+SUM(M30:M34) -> 0 | ... LQ35: =SUM(LQ12:LQ16)+SUM(LQ18:LQ22)+SUM(LQ24:LQ28)+SUM(LQ30:LQ34) -> 0 | MC35: =STDEVP(MG35:MK35) -> 0 | MF35: Total | MG35: =SUM(MG30:MG34)+SUM(MG24:MG28)+SUM(MG18:MG22)+SUM(MG12:MG16) -> 0 | MH35: =SUM(MH30:MH34)+SUM(MH24:MH28)+SUM(MH18:MH22)+SUM(MH12:MH16) -> 0 | MI35: =SUM(MI30:MI34)+SUM(MI24:MI28)+SUM(MI18:MI22)+SUM(MI12:MI16) -> 0 | MJ35: =SUM(MJ30:MJ34)+SUM(MJ24:MJ28)+SUM(MJ18:MJ22)+SUM(MJ12:MJ16) -> 0 | MK35: =SUM(MK30:MK34)+SUM(MK24:MK28)+SUM(MK18:MK22)+SUM(MK12:MK16) -> 0 | ML35: =SUM(ML30:ML34)+SUM(ML24:ML28)+SUM(ML18:ML22)+SUM(ML12:ML16) -> 0 | MM35: =SUM(MM30:MM34)+SUM(MM24:MM28)+SUM(MM18:MM22)+SUM(MM12:MM16) -> 0 | MN35: =SUM(MN30:MN34)+SUM(MN24:MN28)+SUM(MN18:MN22)+SUM(MN12:MN16) -> 0 | ... MU35: =SUM(MU30:MU34)+SUM(MU24:MU28)+SUM(MU18:MU22)+SUM(MU12:MU16) -> 0
DI36: Total Rating | DJ36: =DJ11+DJ17+DJ23+DJ29 -> #DIV/0! | MN36: Total Rating | MO36: =MO11+MO17+MO23+MO29 -> #DIV/0!
B39: Name of Faculty: | DC39: =DC6 -> , | MB39: Rating Period: | MG39: =MG6 -> 0
X41: SUMMARY | AN41: Raw Score | AQ41: Rating | AT41: Weighted
B42: C. SELF AS RATER | I42: =AI43 -> 0.25 | N42: D. SUPERVISOR | U42: =AK43 -> 0.25 | Y42: Rating | AA42: Rank | AE42: ST | AG42: PE | AI42: SE | AK42: SU | AQ42: per Area | AT42: Rating
C43: Rating | E43: Rank | O43: Rating | Q43: Rank | AA43: Group | AB43: Group | AC43: All | AE43: 0.25 | AG43: 0.25 | AH43: 7 | AI43: 0.25 | AJ43: 9 | AK43: 0.25
E44: Group | G44: All | Q44: Group | S44: All | X44: I. Commitment | AI44: 0.25 | AK44: =AVERAGE(Y45:Z49) -> #DIV/0! | AO44: =SUM(Y45:Z49) -> #DIV/0! | AQ44: =AO44*4 -> #DIV/0! | AT44: =AQ44*AI44 -> #DIV/0!
B45: I. Commitment | G45: =AI44 -> 0.25 | I45: =SUM(C46:C50) -> 0 | N45: I. Commitment | S45: =AI44 -> 0.25 | U45: =SUM(O46:O50) -> 0 | X45: 1 | Y45: =AE45*$AE$43+AG45*$AG$43+AI45*$AI$43+AK45*$AK$43 -> #DIV/0! | AA45: =RANK(Y45,$Y$45:$Z$49) -> #DIV/0! | AC45: =RANK(Y45,$Y$45:$Z$67) -> #DIV/0! | AE45: =C12 -> #DIV/0! | AG45: =MD12 -> #DIV/0! | AI45: =C46 -> 0 | AK45: =O46 -> 0
...

Sheet TER
A1: Republic of the Philippines
A2: CAMARINES NORTE STATE COLLEGE
A3: Daet, Camarines Norte
A6: TEACHING EFFICIENCY RATING (TER) FORM 3
A9: Instructor: | D9: =TI!DC6 -> , | H9: Rating Period:
A10: College: | D10: =Entry!D19 -> 0 | H10: Department: | J10: =Entry!D20 -> 0
A12: I. PERFORMANCE: | E12: 0.7 | F12: RATING | H12: RATING | J12: RATING | L12: POINT
H13: EQUIVALENT | J13: PERCENTAGE | L13: SCORE
B14: 1. Instruction
C15: a. Student as Rater | F15: =TI!DJ36 -> #DIV/0! | H15: =F15/10 -> #DIV/0! | J15: 0.25 | L15: =H15*J15 -> #DIV/0!
C16: b. Peer as Rater | F16: =TI!MO36 -> #DIV/0! | H16: =F16/10 -> #DIV/0! | J16: 0.15 | L16: =H16*J16 -> #DIV/0!
C17: c. Dean as Rater | F17: =TI!U69 -> 0 | H17: =F17/10 -> 0 | J17: 0.15 | L17: =H17*J17 -> 0
B19: 2. Research | H19: =F19/10 -> 0 | J19: 0.05 | L19: =H19*J19 -> 0
B20: 3. Extension Service | H20: =F20/10 -> 0 | J20: 0.05 | L20: =H20*J20 -> 0
B21: 4. Productivity | H21: =F21/10 -> 0 | J21: 0.05 | L21: =H21*J21 -> 0
A23: II. BEHAVIOUR | E23: 0.3
B25: 1. Courtesy | H25: 8 | J25: 0.075 | L25: =H25*J25 -> 0.6
B26: 2. Human Relations | H26: 8 | J26: 0.075 | L26: =H26*J26 -> 0.6
B27: 3. Punctuality and Attendance | H27: 8 | J27: 0.075 | L27: =H27*J27 -> 0.6
B28: 4. Initiative | H28: 8 | J28: 0.075 | L28: =H28*J28 -> 0.6
B29: 5. Leadership (For Supervisor only) | J29: 0.05 | L29: =H29*J29 -> 0
B30: 6. Stress Tolerance (For Supervisor only) | J30: 0.05 | L30: =H30*J30 -> 0
B33: For full time instructor --- items 1-4 only at 7.5% per item
B34: For supervisors --- items 1-6 at 5% per item
E35: Overall Point Score | L35: =SUM(L15:L30) -> #DIV/0!
E36: Equivalent Numerical Rating | L36: =IF(L35>=9.3,10,IF(L35>=7.5,8,IF(L35>=5,6,IF(L35>=3,4,2)))) -> #DIV/0!
E37: Equivalent Adjective Rating | L37: =IF(L36=10,"O",IF(L36=8,"VS",IF(L36=6,"S",IF(L36=4,"F","US")))) -> #DIV/0!
A40: Descriptive Equivalent of Numerical Ratings:
C41: 9.3 above | E41: - Outstanding (O)
C42: 7.5 - 9.2 | E42: - Very Satisfactory (VS)
C43: 5.0 - 7.4 | E43: - Satisfactory (S)
C44: 3.0 - 4.9 | E44: - Fair (F)
C45: 2.0 - 2.9 | E45: - Unsatisfactory (US)
A47: EMPLOYEE'S COMMENTS/REMARKS: | H47: DISCUSSED RATING WITH:
H49: =D9 -> ,
H50: Signature of Ratee / Date
A54: RATER'S COMMENTS/REMARKS: | H54: =TI!DZ75 -> DANIEL E. MALIGAT, JR., DIT
H55: Signature of Rater / Date
H60: Signature of Rater's Supervisor / Date

Sheet TR
B1: Republic of the Philippines
B2: CAMARINES NORTE STATE COLLEGE
B3: Daet, Camarines Norte
B5: RATING - RESEARCH
B7: Name of Faculty: | F7: =TI!DC6:DM6 -> #VALUE! | AK7: Rating Period: | AP7: =TI!MG6:MO6 -> #VALUE!
B9: I. CLIENTELE SATISFACTION | J9: 0.2 | L9: =AVERAGE(C12:C16) -> #DIV/0!
C10: Ave. | D10: Rank | E10: Rater No.
E11: 1 | F11: 2 | G11: 3 | H11: 4 | I11: 5 | J11: 6 | K11: 7 | L11: 8 | M11: 9 | N11: 10 | O11: 11 | P11: 12 | Q11: 13 | R11: 14 | S11: 15 | T11: 16 | U11: 17 | V11: 18 | W11: 19 | X11: 20 | Y11: 21 | Z11: 22 | AA11: 23 | AB11: 24 | AC11: 25 | AD11: 26 | AE11: 27 | AF11: 28 | AG11: 29 | AH11: 30 | AI11: 31 | AJ11: 32 | AK11: 33 | AL11: 34 | AM11: 35 | AN11: 36 | AO11: 37 | AP11: 38 | AQ11: 39 | AR11: 40 | AS11: 41 | AT11: 42 | AU11: 43 | AV11: 44 | AW11: 45 | AX11: 46 | AY11: 47 | AZ11: 48 | BA11: 49 | BB11: 50
B12: 1 | C12: =AVERAGE(E12:BB12,E19:BB19,E26:BB26,E33:BB33) -> #DIV/0! | D12: =RANK(C12,$C$12:$C$16) -> #DIV/0!
B13: 2 | C13: =AVERAGE(E13:BB13,E20:BB20,E27:BB27,E34:BB34) -> #DIV/0! | D13: =RANK(C13,$C$12:$C$16) -> #DIV/0!
B14: 3 | C14: =AVERAGE(E14:BB14,E21:BB21,E28:BB28,E35:BB35) -> #DIV/0! | D14: =RANK(C14,$C$12:$C$16) -> #DIV/0!
B15: 4 | C15: =AVERAGE(E15:BB15,E22:BB22,E29:BB29,E36:BB36) -> #DIV/0! | D15: =RANK(C15,$C$12:$C$16) -> #DIV/0!
B16: 5 | C16: =AVERAGE(E16:BB16,E23:BB23,E30:BB30,E37:BB37) -> #DIV/0! | D16: =RANK(C16,$C$12:$C$16) -> #DIV/0!
E17: Rater No.
E18: 51 | F18: 52 | G18: 53 | H18: 54 | I18: 55 | J18: 56 | K18: 57 | L18: 58 | M18: 59 | N18: 60 | O18: 61 | P18: 62 | Q18: 63 | R18: 64 | S18: 65 | T18: 66 | U18: 67 | V18: 68 | W18: 69 | X18: 70 | Y18: 71 | Z18: 72 | AA18: 73 | AB18: 74 | AC18: 75 | AD18: 76 | AE18: 77 | AF18: 78 | AG18: 79 | AH18: 80 | AI18: 81 | AJ18: 82 | AK18: 83 | AL18: 84 | AM18: 85 | AN18: 86 | AO18: 87 | AP18: 88 | AQ18: 89 | AR18: 90 | AS18: 91 | AT18: 92 | AU18: 93 | AV18: 94 | AW18: 95 | AX18: 96 | AY18: 97 | AZ18: 98 | BA18: 99 | BB18: 100
E24: Rater No.
E25: 101 | F25: 102 | G25: 103 | H25: 104 | I25: 105 | J25: 106 | K25: 107 | L25: 108 | M25: 109 | N25: 110 | O25: 111 | P25: 112 | Q25: 113 | R25: 114 | S25: 115 | T25: 116 | U25: 117 | V25: 118 | W25: 119 | X25: 120 | Y25: 121 | Z25: 122 | AA25: 123 | AB25: 124 | AC25: 125 | AD25: 126 | AE25: 127 | AF25: 128 | AG25: 129 | AH25: 130 | AI25: 131 | AJ25: 132 | AK25: 133 | AL25: 134 | AM25: 135 | AN25: 136 | AO25: 137 | AP25: 138 | AQ25: 139 | AR25: 140 | AS25: 141 | AT25: 142 | AU25: 143 | AV25: 144 | AW25: 145 | AX25: 146 | AY25: 147 | AZ25: 148 | BA25: 149 | BB25: 150
E31: Rater No.
E32: 151 | F32: 152 | G32: 153 | H32: 154 | I32: 155 | J32: 156 | K32: 157 | L32: 158 | M32: 159 | N32: 160 | O32: 161 | P32: 162 | Q32: 163 | R32: 164 | S32: 165 | T32: 166 | U32: 167 | V32: 168 | W32: 169 | X32: 170 | Y32: 171 | Z32: 172 | AA32: 173 | AB32: 174 | AC32: 175 | AD32: 176 | AE32: 177 | AF32: 178 | AG32: 179 | AH32: 180 | AI32: 181 | AJ32: 182 | AK32: 183 | AL32: 184 | AM32: 185 | AN32: 186 | AO32: 187 | AP32: 188 | AQ32: 189 | AR32: 190 | AS32: 191 | AT32: 192 | AU32: 193 | AV32: 194 | AW32: 195 | AX32: 196 | AY32: 197 | AZ32: 198 | BA32: 199 | BB32: 200
B40: II. LEADERSHIP | H40: III. PARTNERSHIP DEVELOPMENT | R40: IV. COMMUNITY RESPONSIBILITY | AC40: 0.3 | AE40: =AVERAGE(S43:S47) -> #DIV/0! | AU40: CERTIFIED CORRECT:
C41: Rating | D41: Rank | E41: 0.2 | I41: Ave. | J41: Rank | K41: Rater No. | O41: 0.3 | S41: Ave. | T41: Rank | U41: Rater No.
E42: =AVERAGE(C43:C47) -> #DIV/0! | K42: 1 | L42: 2 | M42: 3 | N42: 4 | O42: =AVERAGE(I43:I47) -> #DIV/0! | U42: 1 | V42: 2 | W42: 3 | X42: 4 | Y42: 5 | Z42: 6 | AA42: 7 | AB42: 8 | AC42: 9 | AD42: 10 | AE42: 11 | AF42: 12 | AI42: SUMMARY - RESEARCH
B43: 1 | D43: =RANK(C43,$C$43:$C$47) -> #N/A | H43: 1 | I43: =AVERAGE(K43:N43) -> #DIV/0! | J43: =RANK(I43,$I$43:$I$47) -> #DIV/0! | R43: 1 | S43: =AVERAGE(U43:AF43) -> #DIV/0! | T43: =RANK(S43,$S$43:$S$47) -> #DIV/0! | AI43: I. Clientele Satisfaction | AO43: =L9 -> #DIV/0! | AP43: =AO43*20 -> #DIV/0!
B44: 2 | D44: =RANK(C44,$C$43:$C$47) -> #N/A | H44: 2 | I44: =AVERAGE(K44:N44) -> #DIV/0! | J44: =RANK(I44,$I$43:$I$47) -> #DIV/0! | R44: 2 | S44: =AVERAGE(U44:AF44) -> #DIV/0! | T44: =RANK(S44,$S$43:$S$47) -> #DIV/0! | AI44: II. Leadership | AO44: =E42 -> #DIV/0! | AP44: =AO44*20 -> #DIV/0!
B45: 3 | D45: =RANK(C45,$C$43:$C$47) -> #N/A | H45: 3 | I45: =AVERAGE(K45:N45) -> #DIV/0! | J45: =RANK(I45,$I$43:$I$47) -> #DIV/0! | R45: 3 | S45: =AVERAGE(U45:AF45) -> #DIV/0! | T45: =RANK(S45,$S$43:$S$47) -> #DIV/0! | AI45: III. Partnership Development | AO45: =O42 -> #DIV/0! | AP45: =AO45*20 -> #DIV/0! | AU45: =TI!DZ75 -> DANIEL E. MALIGAT, JR., DIT
B46: 4 | D46: =RANK(C46,$C$43:$C$47) -> #N/A | H46: 4 | I46: =AVERAGE(K46:N46) -> #DIV/0! | J46: =RANK(I46,$I$43:$I$47) -> #DIV/0! | R46: 4 | S46: =AVERAGE(U46:AF46) -> #DIV/0! | T46: =RANK(S46,$S$43:$S$47) -> #DIV/0! | AI46: IV. Community Responsibility | AO46: =AE40 -> #DIV/0! | AP46: =AO46*20 -> #DIV/0! | AU46: =TI!DZ76 -> DEAN
B47: 5 | D47: =RANK(C47,$C$43:$C$47) -> #N/A | H47: 5 | I47: =AVERAGE(K47:N47) -> #DIV/0! | J47: =RANK(I47,$I$43:$I$47) -> #DIV/0! | R47: 5 | S47: =AVERAGE(U47:AF47) -> #DIV/0! | T47: =RANK(S47,$S$43:$S$47) -> #DIV/0!

Sheet TE
B1: Republic of the Philippines
B2: CAMARINES NORTE STATE COLLEGE
B3: Daet, Camarines Norte
B5: RATING - EXTENSION
B7: Name of Faculty: | F7: =TI!DC6:DM6 -> #VALUE! | AK7: Rating Period: | AP7: =TI!MG6:MO6 -> #VALUE!
B9: I. CLIENTELE SATISFACTION | J9: =TR!J9 -> 0.2 | L9: =AVERAGE(C12:C16) -> #DIV/0!
C10: Ave. | D10: Rank | E10: Rater No.
E11: 1 | F11: 2 | G11: 3 | H11: 4 | I11: 5 | J11: 6 | K11: 7 | L11: 8 | M11: 9 | N11: 10 | O11: 11 | P11: 12 | Q11: 13 | R11: 14 | S11: 15 | T11: 16 | U11: 17 | V11: 18 | W11: 19 | X11: 20 | Y11: 21 | Z11: 22 | AA11: 23 | AB11: 24 | AC11: 25 | AD11: 26 | AE11: 27 | AF11: 28 | AG11: 29 | AH11: 30 | AI11: 31 | AJ11: 32 | AK11: 33 | AL11: 34 | AM11: 35 | AN11: 36 | AO11: 37 | AP11: 38 | AQ11: 39 | AR11: 40 | AS11: 41 | AT11: 42 | AU11: 43 | AV11: 44 | AW11: 45 | AX11: 46 | AY11: 47 | AZ11: 48 | BA11: 49 | BB11: 50
B12: 1 | C12: =AVERAGE(E12:BB12,E19:BB19,E26:BB26,E33:BB33) -> #DIV/0! | D12: =RANK(C12,$C$12:$C$16) -> #DIV/0!
B13: 2 | C13: =AVERAGE(E13:BB13,E20:BB20,E27:BB27,E34:BB34) -> #DIV/0! | D13: =RANK(C13,$C$12:$C$16) -> #DIV/0!
B14: 3 | C14: =AVERAGE(E14:BB14,E21:BB21,E28:BB28,E35:BB35) -> #DIV/0! | D14: =RANK(C14,$C$12:$C$16) -> #DIV/0!
B15: 4 | C15: =AVERAGE(E15:BB15,E22:BB22,E29:BB29,E36:BB36) -> #DIV/0! | D15: =RANK(C15,$C$12:$C$16) -> #DIV/0!
B16: 5 | C16: =AVERAGE(E16:BB16,E23:BB23,E30:BB30,E37:BB37) -> #DIV/0! | D16: =RANK(C16,$C$12:$C$16) -> #DIV/0!
E17: Rater No.
E18: 51 | F18: 52 | G18: 53 | H18: 54 | I18: 55 | J18: 56 | K18: 57 | L18: 58 | M18: 59 | N18: 60 | O18: 61 | P18: 62 | Q18: 63 | R18: 64 | S18: 65 | T18: 66 | U18: 67 | V18: 68 | W18: 69 | X18: 70 | Y18: 71 | Z18: 72 | AA18: 73 | AB18: 74 | AC18: 75 | AD18: 76 | AE18: 77 | AF18: 78 | AG18: 79 | AH18: 80 | AI18: 81 | AJ18: 82 | AK18: 83 | AL18: 84 | AM18: 85 | AN18: 86 | AO18: 87 | AP18: 88 | AQ18: 89 | AR18: 90 | AS18: 91 | AT18: 92 | AU18: 93 | AV18: 94 | AW18: 95 | AX18: 96 | AY18: 97 | AZ18: 98 | BA18: 99 | BB18: 100
E24: Rater No.
E25: 101 | F25: 102 | G25: 103 | H25: 104 | I25: 105 | J25: 106 | K25: 107 | L25: 108 | M25: 109 | N25: 110 | O25: 111 | P25: 112 | Q25: 113 | R25: 114 | S25: 115 | T25: 116 | U25: 117 | V25: 118 | W25: 119 | X25: 120 | Y25: 121 | Z25: 122 | AA25: 123 | AB25: 124 | AC25: 125 | AD25: 126 | AE25: 127 | AF25: 128 | AG25: 129 | AH25: 130 | AI25: 131 | AJ25: 132 | AK25: 133 | AL25: 134 | AM25: 135 | AN25: 136 | AO25: 137 | AP25: 138 | AQ25: 139 | AR25: 140 | AS25: 141 | AT25: 142 | AU25: 143 | AV25: 144 | AW25: 145 | AX25: 146 | AY25: 147 | AZ25: 148 | BA25: 149 | BB25: 150
E31: Rater No.
E32: 151 | F32: 152 | G32: 153 | H32: 154 | I32: 155 | J32: 156 | K32: 157 | L32: 158 | M32: 159 | N32: 160 | O32: 161 | P32: 162 | Q32: 163 | R32: 164 | S32: 165 | T32: 166 | U32: 167 | V32: 168 | W32: 169 | X32: 170 | Y32: 171 | Z32: 172 | AA32: 173 | AB32: 174 | AC32: 175 | AD32: 176 | AE32: 177 | AF32: 178 | AG32: 179 | AH32: 180 | AI32: 181 | AJ32: 182 | AK32: 183 | AL32: 184 | AM32: 185 | AN32: 186 | AO32: 187 | AP32: 188 | AQ32: 189 | AR32: 190 | AS32: 191 | AT32: 192 | AU32: 193 | AV32: 194 | AW32: 195 | AX32: 196 | AY32: 197 | AZ32: 198 | BA32: 199 | BB32: 200
B40: II. LEADERSHIP | H40: III. PARTNERSHIP DEVELOPMENT | R40: IV. COMMUNITY RESPONSIBILITY | AC40: 0.3 | AE40: =AVERAGE(S43:S47) -> #DIV/0! | AU40: CERTIFIED CORRECT:
C41: Rating | D41: Rank | E41: 0.2 | I41: Ave. | J41: Rank | K41: Rater No. | O41: 0.3 | S41: Ave. | T41: Rank | U41: Rater No.
E42: =AVERAGE(C43:C47) -> #DIV/0! | K42: 1 | L42: 2 | M42: 3 | N42: 4 | O42: =AVERAGE(I43:I47) -> #DIV/0! | U42: 1 | V42: 2 | W42: 3 | X42: 4 | Y42: 5 | Z42: 6 | AA42: 7 | AB42: 8 | AC42: 9 | AD42: 10 | AE42: 11 | AF42: 12 | AI42: SUMMARY - EXTENSION
B43: 1 | D43: =RANK(C43,$C$43:$C$47) -> #N/A | H43: 1 | I43: =AVERAGE(K43:N43) -> #DIV/0! | J43: =RANK(I43,$I$43:$I$47) -> #DIV/0! | R43: 1 | S43: =AVERAGE(U43:AF43) -> #DIV/0! | T43: =RANK(S43,$S$43:$S$47) -> #DIV/0! | AI43: =TR!AI43 -> I. Clientele Satisfaction | AO43: =L9 -> #DIV/0! | AP43: =AO43*20 -> #DIV/0!
B44: 2 | D44: =RANK(C44,$C$43:$C$47) -> #N/A | H44: 2 | I44: =AVERAGE(K44:N44) -> #DIV/0! | J44: =RANK(I44,$I$43:$I$47) -> #DIV/0! | R44: 2 | S44: =AVERAGE(U44:AF44) -> #DIV/0! | T44: =RANK(S44,$S$43:$S$47) -> #DIV/0! | AI44: =TR!AI44 -> II. Leadership | AO44: =E42 -> #DIV/0! | AP44: =AO44*20 -> #DIV/0!
B45: 3 | D45: =RANK(C45,$C$43:$C$47) -> #N/A | H45: 3 | I45: =AVERAGE(K45:N45) -> #DIV/0! | J45: =RANK(I45,$I$43:$I$47) -> #DIV/0! | R45: 3 | S45: =AVERAGE(U45:AF45) -> #DIV/0! | T45: =RANK(S45,$S$43:$S$47) -> #DIV/0! | AI45: =TR!AI45 -> III. Partnership Development | AO45: =O42 -> #DIV/0! | AP45: =AO45*20 -> #DIV/0! | AU45: =TI!DZ75 -> DANIEL E. MALIGAT, JR., DIT
B46: 4 | D46: =RANK(C46,$C$43:$C$47) -> #N/A | H46: 4 | I46: =AVERAGE(K46:N46) -> #DIV/0! | J46: =RANK(I46,$I$43:$I$47) -> #DIV/0! | R46: 4 | S46: =AVERAGE(U46:AF46) -> #DIV/0! | T46: =RANK(S46,$S$43:$S$47) -> #DIV/0! | AI46: =TR!AI46 -> IV. Community Responsibility | AO46: =AE40 -> #DIV/0! | AP46: =AO46*20 -> #DIV/0! | AU46: =TI!DZ76 -> DEAN
B47: 5 | D47: =RANK(C47,$C$43:$C$47) -> #N/A | H47: 5 | I47: =AVERAGE(K47:N47) -> #DIV/0! | J47: =RANK(I47,$I$43:$I$47) -> #DIV/0! | R47: 5 | S47: =AVERAGE(U47:AF47) -> #DIV/0! | T47: =RANK(S47,$S$43:$S$47) -> #DIV/0!

Sheet TP
B1: Republic of the Philippines
B2: CAMARINES NORTE STATE COLLEGE
B3: Daet, Camarines Norte
B5: RATING - PRODUCTION
B7: Name of Faculty: | F7: =TI!DC6:DM6 -> #VALUE! | AK7: Rating Period: | AP7: =TI!MG6:MO6 -> #VALUE!
B9: I. CLIENTELE SATISFACTION | J9: =TR!J9 -> 0.2 | L9: =AVERAGE(C12:C16) -> #DIV/0!
C10: Ave. | D10: Rank | E10: Rater No.
E11: 1 | F11: 2 | G11: 3 | H11: 4 | I11: 5 | J11: 6 | K11: 7 | L11: 8 | M11: 9 | N11: 10 | O11: 11 | P11: 12 | Q11: 13 | R11: 14 | S11: 15 | T11: 16 | U11: 17 | V11: 18 | W11: 19 | X11: 20 | Y11: 21 | Z11: 22 | AA11: 23 | AB11: 24 | AC11: 25 | AD11: 26 | AE11: 27 | AF11: 28 | AG11: 29 | AH11: 30 | AI11: 31 | AJ11: 32 | AK11: 33 | AL11: 34 | AM11: 35 | AN11: 36 | AO11: 37 | AP11: 38 | AQ11: 39 | AR11: 40 | AS11: 41 | AT11: 42 | AU11: 43 | AV11: 44 | AW11: 45 | AX11: 46 | AY11: 47 | AZ11: 48 | BA11: 49 | BB11: 50
B12: 1 | C12: =AVERAGE(E12:BB12,E19:BB19,E26:BB26,E33:BB33) -> #DIV/0! | D12: =RANK(C12,$C$12:$C$16) -> #DIV/0!
B13: 2 | C13: =AVERAGE(E13:BB13,E20:BB20,E27:BB27,E34:BB34) -> #DIV/0! | D13: =RANK(C13,$C$12:$C$16) -> #DIV/0!
B14: 3 | C14: =AVERAGE(E14:BB14,E21:BB21,E28:BB28,E35:BB35) -> #DIV/0! | D14: =RANK(C14,$C$12:$C$16) -> #DIV/0!
B15: 4 | C15: =AVERAGE(E15:BB15,E22:BB22,E29:BB29,E36:BB36) -> #DIV/0! | D15: =RANK(C15,$C$12:$C$16) -> #DIV/0!
B16: 5 | C16: =AVERAGE(E16:BB16,E23:BB23,E30:BB30,E37:BB37) -> #DIV/0! | D16: =RANK(C16,$C$12:$C$16) -> #DIV/0!
E17: Rater No.
E18: 51 | F18: 52 | G18: 53 | H18: 54 | I18: 55 | J18: 56 | K18: 57 | L18: 58 | M18: 59 | N18: 60 | O18: 61 | P18: 62 | Q18: 63 | R18: 64 | S18: 65 | T18: 66 | U18: 67 | V18: 68 | W18: 69 | X18: 70 | Y18: 71 | Z18: 72 | AA18: 73 | AB18: 74 | AC18: 75 | AD18: 76 | AE18: 77 | AF18: 78 | AG18: 79 | AH18: 80 | AI18: 81 | AJ18: 82 | AK18: 83 | AL18: 84 | AM18: 85 | AN18: 86 | AO18: 87 | AP18: 88 | AQ18: 89 | AR18: 90 | AS18: 91 | AT18: 92 | AU18: 93 | AV18: 94 | AW18: 95 | AX18: 96 | AY18: 97 | AZ18: 98 | BA18: 99 | BB18: 100
E24: Rater No.
E25: 101 | F25: 102 | G25: 103 | H25: 104 | I25: 105 | J25: 106 | K25: 107 | L25: 108 | M25: 109 | N25: 110 | O25: 111 | P25: 112 | Q25: 113 | R25: 114 | S25: 115 | T25: 116 | U25: 117 | V25: 118 | W25: 119 | X25: 120 | Y25: 121 | Z25: 122 | AA25: 123 | AB25: 124 | AC25: 125 | AD25: 126 | AE25: 127 | AF25: 128 | AG25: 129 | AH25: 130 | AI25: 131 | AJ25: 132 | AK25: 133 | AL25: 134 | AM25: 135 | AN25: 136 | AO25: 137 | AP25: 138 | AQ25: 139 | AR25: 140 | AS25: 141 | AT25: 142 | AU25: 143 | AV25: 144 | AW25: 145 | AX25: 146 | AY25: 147 | AZ25: 148 | BA25: 149 | BB25: 150
E31: Rater No.
E32: 151 | F32: 152 | G32: 153 | H32: 154 | I32: 155 | J32: 156 | K32: 157 | L32: 158 | M32: 159 | N32: 160 | O32: 161 | P32: 162 | Q32: 163 | R32: 164 | S32: 165 | T32: 166 | U32: 167 | V32: 168 | W32: 169 | X32: 170 | Y32: 171 | Z32: 172 | AA32: 173 | AB32: 174 | AC32: 175 | AD32: 176 | AE32: 177 | AF32: 178 | AG32: 179 | AH32: 180 | AI32: 181 | AJ32: 182 | AK32: 183 | AL32: 184 | AM32: 185 | AN32: 186 | AO32: 187 | AP32: 188 | AQ32: 189 | AR32: 190 | AS32: 191 | AT32: 192 | AU32: 193 | AV32: 194 | AW32: 195 | AX32: 196 | AY32: 197 | AZ32: 198 | BA32: 199 | BB32: 200
B40: II. LEADERSHIP | H40: III. PARTNERSHIP DEVELOPMENT | R40: IV. COMMUNITY RESPONSIBILITY | AC40: 0.3 | AE40: =AVERAGE(S43:S47) -> #DIV/0! | AU40: CERTIFIED CORRECT:
C41: Rating | D41: Rank | E41: 0.2 | I41: Ave. | J41: Rank | K41: Rater No. | O41: 0.3 | S41: Ave. | T41: Rank | U41: Rater No.
E42: =AVERAGE(C43:C47) -> #DIV/0! | K42: 1 | L42: 2 | M42: 3 | N42: 4 | O42: =AVERAGE(I43:I47) -> #DIV/0! | U42: 1 | V42: 2 | W42: 3 | X42: 4 | Y42: 5 | Z42: 6 | AA42: 7 | AB42: 8 | AC42: 9 | AD42: 10 | AE42: 11 | AF42: 12 | AI42: SUMMARY - PRODUCTION
B43: 1 | D43: =RANK(C43,$C$43:$C$47) -> #N/A | H43: 1 | I43: =AVERAGE(K43:N43) -> #DIV/0! | J43: =RANK(I43,$I$43:$I$47) -> #DIV/0! | R43: 1 | S43: =AVERAGE(U43:AF43) -> #DIV/0! | T43: =RANK(S43,$S$43:$S$47) -> #DIV/0! | AI43: =TR!AI43 -> I. Clientele Satisfaction | AO43: =L9 -> #DIV/0! | AP43: =AO43*20 -> #DIV/0!
B44: 2 | D44: =RANK(C44,$C$43:$C$47) -> #N/A | H44: 2 | I44: =AVERAGE(K44:N44) -> #DIV/0! | J44: =RANK(I44,$I$43:$I$47) -> #DIV/0! | R44: 2 | S44: =AVERAGE(U44:AF44) -> #DIV/0! | T44: =RANK(S44,$S$43:$S$47) -> #DIV/0! | AI44: =TR!AI44 -> II. Leadership | AO44: =E42 -> #DIV/0! | AP44: =AO44*20 -> #DIV/0!
B45: 3 | D45: =RANK(C45,$C$43:$C$47) -> #N/A | H45: 3 | I45: =AVERAGE(K45:N45) -> #DIV/0! | J45: =RANK(I45,$I$43:$I$47) -> #DIV/0! | R45: 3 | S45: =AVERAGE(U45:AF45) -> #DIV/0! | T45: =RANK(S45,$S$43:$S$47) -> #DIV/0! | AI45: =TR!AI45 -> III. Partnership Development | AO45: =O42 -> #DIV/0! | AP45: =AO45*20 -> #DIV/0! | AU45: =TI!DZ75 -> DANIEL E. MALIGAT, JR., DIT
B46: 4 | D46: =RANK(C46,$C$43:$C$47) -> #N/A | H46: 4 | I46: =AVERAGE(K46:N46) -> #DIV/0! | J46: =RANK(I46,$I$43:$I$47) -> #DIV/0! | R46: 4 | S46: =AVERAGE(U46:AF46) -> #DIV/0! | T46: =RANK(S46,$S$43:$S$47) -> #DIV/0! | AI46: =TR!AI46 -> IV. Community Responsibility | AO46: =AE40 -> #DIV/0! | AP46: =AO46*20 -> #DIV/0! | AU46: =TI!DZ76 -> DEAN
B47: 5 | D47: =RANK(C47,$C$43:$C$47) -> #N/A | H47: 5 | I47: =AVERAGE(K47:N47) -> #DIV/0! | J47: =RANK(I47,$I$43:$I$47) -> #DIV/0! | R47: 5 | S47: =AVERAGE(U47:AF47) -> #DIV/0! | T47: =RANK(S47,$S$43:$S$47) -> #DIV/0!

Sheet 02A-S
B1: NBC 461- QCE FORM 02A
B4: CAMARINES NORTE STATE COLLEGE
B5: Daet, Camarines Norte
B7: SECTORAL FREQUENCY OF RATING PER AREA
B8: FOR INSTRUCTORS AND ASSISTANT PROFESSORS
C9: SECTORAL EVALUATOR | E9: STUDENTS
B12: NAME OF FACULTY | C12: =TI!DC6 -> ,
B13: RATING PERIOD | C13: =TI!MG6 -> 0
B15: INSTRUCTION
B16: I. COMMITMENT
B17: CRITERIA | C17: RATING SCALE (1-Lowest, 5-Highest) | H17: AVERAGE
B18: NUMBER | C18: 1 | D18: 2 | E18: 3 | F18: 4 | G18: 5 | H18: RATING
B19: 1 | C19: =COUNTIF(TI!$DC12:$EF12,"=1") -> 0 | D19: =COUNTIF(TI!$DC12:$EF12,"=2") -> 0 | E19: =COUNTIF(TI!$DC12:$EF12,"=3") -> 0 | F19: =COUNTIF(TI!$DC12:$EF12,"=4") -> 0 | G19: =COUNTIF(TI!$DC12:$EF12,"=5") -> 0 | H19: {=IF(SUM(C19:G19)=0,,SUM((C19:G19)*($C$18:$G$18))/SUM(C19:G19))} -> 0
B20: 2 | C20: =COUNTIF(TI!$DC13:$EF13,"=1") -> 0 | D20: =COUNTIF(TI!$DC13:$EF13,"=2") -> 0 | E20: =COUNTIF(TI!$DC13:$EF13,"=3") -> 0 | F20: =COUNTIF(TI!$DC13:$EF13,"=4") -> 0 | G20: =COUNTIF(TI!$DC13:$EF13,"=5") -> 0 | H20: {=IF(SUM(C20:G20)=0,,SUM((C20:G20)*($C$18:$G$18))/SUM(C20:G20))} -> 0
B21: 3 | C21: =COUNTIF(TI!$DC14:$EF14,"=1") -> 0 | D21: =COUNTIF(TI!$DC14:$EF14,"=2") -> 0 | E21: =COUNTIF(TI!$DC14:$EF14,"=3") -> 0 | F21: =COUNTIF(TI!$DC14:$EF14,"=4") -> 0 | G21: =COUNTIF(TI!$DC14:$EF14,"=5") -> 0 | H21: {=IF(SUM(C21:G21)=0,,SUM((C21:G21)*($C$18:$G$18))/SUM(C21:G21))} -> 0
B22: 4 | C22: =COUNTIF(TI!$DC15:$EF15,"=1") -> 0 | D22: =COUNTIF(TI!$DC15:$EF15,"=2") -> 0 | E22: =COUNTIF(TI!$DC15:$EF15,"=3") -> 0 | F22: =COUNTIF(TI!$DC15:$EF15,"=4") -> 0 | G22: =COUNTIF(TI!$DC15:$EF15,"=5") -> 0 | H22: {=IF(SUM(C22:G22)=0,,SUM((C22:G22)*($C$18:$G$18))/SUM(C22:G22))} -> 0
B23: 5 | C23: =COUNTIF(TI!$DC16:$EF16,"=1") -> 0 | D23: =COUNTIF(TI!$DC16:$EF16,"=2") -> 0 | E23: =COUNTIF(TI!$DC16:$EF16,"=3") -> 0 | F23: =COUNTIF(TI!$DC16:$EF16,"=4") -> 0 | G23: =COUNTIF(TI!$DC16:$EF16,"=5") -> 0 | H23: {=IF(SUM(C23:G23)=0,,SUM((C23:G23)*($C$18:$G$18))/SUM(C23:G23))} -> 0
B24: TOTAL AREA RATING | C24: =SUM(C19:C23)*C$18 -> 0 | D24: =SUM(D19:D23)*D$18 -> 0 | E24: =SUM(E19:E23)*E$18 -> 0 | F24: =SUM(F19:F23)*F$18 -> 0 | G24: =SUM(G19:G23)*G$18 -> 0 | H24: =SUM(H19:H23)*4 -> 0
B26: II. KNOWLEDGE OF SUBJECT
B27: 1 | C27: =COUNTIF(TI!$DC18:$EF18,"=1") -> 0 | D27: =COUNTIF(TI!$DC18:$EF18,"=2") -> 0 | E27: =COUNTIF(TI!$DC18:$EF18,"=3") -> 0 | F27: =COUNTIF(TI!$DC18:$EF18,"=4") -> 0 | G27: =COUNTIF(TI!$DC18:$EF18,"=5") -> 0 | H27: {=IF(SUM(C27:G27)=0,,SUM((C27:G27)*($C$18:$G$18))/SUM(C27:G27))} -> 0
B28: 2 | C28: =COUNTIF(TI!$DC19:$EF19,"=1") -> 0 | D28: =COUNTIF(TI!$DC19:$EF19,"=2") -> 0 | E28: =COUNTIF(TI!$DC19:$EF19,"=3") -> 0 | F28: =COUNTIF(TI!$DC19:$EF19,"=4") -> 0 | G28: =COUNTIF(TI!$DC19:$EF19,"=5") -> 0 | H28: {=IF(SUM(C28:G28)=0,,SUM((C28:G28)*($C$18:$G$18))/SUM(C28:G28))} -> 0
B29: 3 | C29: =COUNTIF(TI!$DC20:$EF20,"=1") -> 0 | D29: =COUNTIF(TI!$DC20:$EF20,"=2") -> 0 | E29: =COUNTIF(TI!$DC20:$EF20,"=3") -> 0 | F29: =COUNTIF(TI!$DC20:$EF20,"=4") -> 0 | G29: =COUNTIF(TI!$DC20:$EF20,"=5") -> 0 | H29: {=IF(SUM(C29:G29)=0,,SUM((C29:G29)*($C$18:$G$18))/SUM(C29:G29))} -> 0
B30: 4 | C30: =COUNTIF(TI!$DC21:$EF21,"=1") -> 0 | D30: =COUNTIF(TI!$DC21:$EF21,"=2") -> 0 | E30: =COUNTIF(TI!$DC21:$EF21,"=3") -> 0 | F30: =COUNTIF(TI!$DC21:$EF21,"=4") -> 0 | G30: =COUNTIF(TI!$DC21:$EF21,"=5") -> 0 | H30: {=IF(SUM(C30:G30)=0,,SUM((C30:G30)*($C$18:$G$18))/SUM(C30:G30))} -> 0
B31: 5 | C31: =COUNTIF(TI!$DC22:$EF22,"=1") -> 0 | D31: =COUNTIF(TI!$DC22:$EF22,"=2") -> 0 | E31: =COUNTIF(TI!$DC22:$EF22,"=3") -> 0 | F31: =COUNTIF(TI!$DC22:$EF22,"=4") -> 0 | G31: =COUNTIF(TI!$DC22:$EF22,"=5") -> 0 | H31: {=IF(SUM(C31:G31)=0,,SUM((C31:G31)*($C$18:$G$18))/SUM(C31:G31))} -> 0
B32: TOTAL AREA RATING | C32: =SUM(C27:C31)*C$18 -> 0 | D32: =SUM(D27:D31)*D$18 -> 0 | E32: =SUM(E27:E31)*E$18 -> 0 | F32: =SUM(F27:F31)*F$18 -> 0 | G32: =SUM(G27:G31)*G$18 -> 0 | H32: =SUM(H27:H31)*4 -> 0
B34: III. TEACHING FOR INDEPENDENT LEARNING
B35: 1 | C35: =COUNTIF(TI!$DC24:$EF24,"=1") -> 0 | D35: =COUNTIF(TI!$DC24:$EF24,"=2") -> 0 | E35: =COUNTIF(TI!$DC24:$EF24,"=3") -> 0 | F35: =COUNTIF(TI!$DC24:$EF24,"=4") -> 0 | G35: =COUNTIF(TI!$DC24:$EF24,"=5") -> 0 | H35: {=IF(SUM(C35:G35)=0,,SUM((C35:G35)*($C$18:$G$18))/SUM(C35:G35))} -> 0
B36: 2 | C36: =COUNTIF(TI!$DC25:$EF25,"=1") -> 0 | D36: =COUNTIF(TI!$DC25:$EF25,"=2") -> 0 | E36: =COUNTIF(TI!$DC25:$EF25,"=3") -> 0 | F36: =COUNTIF(TI!$DC25:$EF25,"=4") -> 0 | G36: =COUNTIF(TI!$DC25:$EF25,"=5") -> 0 | H36: {=IF(SUM(C36:G36)=0,,SUM((C36:G36)*($C$18:$G$18))/SUM(C36:G36))} -> 0
B37: 3 | C37: =COUNTIF(TI!$DC26:$EF26,"=1") -> 0 | D37: =COUNTIF(TI!$DC26:$EF26,"=2") -> 0 | E37: =COUNTIF(TI!$DC26:$EF26,"=3") -> 0 | F37: =COUNTIF(TI!$DC26:$EF26,"=4") -> 0 | G37: =COUNTIF(TI!$DC26:$EF26,"=5") -> 0 | H37: {=IF(SUM(C37:G37)=0,,SUM((C37:G37)*($C$18:$G$18))/SUM(C37:G37))} -> 0
B38: 4 | C38: =COUNTIF(TI!$DC27:$EF27,"=1") -> 0 | D38: =COUNTIF(TI!$DC27:$EF27,"=2") -> 0 | E38: =COUNTIF(TI!$DC27:$EF27,"=3") -> 0 | F38: =COUNTIF(TI!$DC27:$EF27,"=4") -> 0 | G38: =COUNTIF(TI!$DC27:$EF27,"=5") -> 0 | H38: {=IF(SUM(C38:G38)=0,,SUM((C38:G38)*($C$18:$G$18))/SUM(C38:G38))} -> 0
B39: 5 | C39: =COUNTIF(TI!$DC28:$EF28,"=1") -> 0 | D39: =COUNTIF(TI!$DC28:$EF28,"=2") -> 0 | E39: =COUNTIF(TI!$DC28:$EF28,"=3") -> 0 | F39: =COUNTIF(TI!$DC28:$EF28,"=4") -> 0 | G39: =COUNTIF(TI!$DC28:$EF28,"=5") -> 0 | H39: {=IF(SUM(C39:G39)=0,,SUM((C39:G39)*($C$18:$G$18))/SUM(C39:G39))} -> 0
B40: TOTAL AREA RATING | C40: =SUM(C35:C39)*C$18 -> 0 | D40: =SUM(D35:D39)*D$18 -> 0 | E40: =SUM(E35:E39)*E$18 -> 0 | F40: =SUM(F35:F39)*F$18 -> 0 | G40: =SUM(G35:G39)*G$18 -> 0 | H40: =SUM(H35:H39)*4 -> 0
B42: IV. MANAGEMENT OF LEARNING
B43: 1 | C43: =COUNTIF(TI!$DC30:$EF30,"=1") -> 0 | D43: =COUNTIF(TI!$DC30:$EF30,"=2") -> 0 | E43: =COUNTIF(TI!$DC30:$EF30,"=3") -> 0 | F43: =COUNTIF(TI!$DC30:$EF30,"=4") -> 0 | G43: =COUNTIF(TI!$DC30:$EF30,"=5") -> 0 | H43: {=IF(SUM(C43:G43)=0,,SUM((C43:G43)*($C$18:$G$18))/SUM(C43:G43))} -> 0
B44: 2 | C44: =COUNTIF(TI!$DC31:$EF31,"=1") -> 0 | D44: =COUNTIF(TI!$DC31:$EF31,"=2") -> 0 | E44: =COUNTIF(TI!$DC31:$EF31,"=3") -> 0 | F44: =COUNTIF(TI!$DC31:$EF31,"=4") -> 0 | G44: =COUNTIF(TI!$DC31:$EF31,"=5") -> 0 | H44: {=IF(SUM(C44:G44)=0,,SUM((C44:G44)*($C$18:$G$18))/SUM(C44:G44))} -> 0
B45: 3 | C45: =COUNTIF(TI!$DC32:$EF32,"=1") -> 0 | D45: =COUNTIF(TI!$DC32:$EF32,"=2") -> 0 | E45: =COUNTIF(TI!$DC32:$EF32,"=3") -> 0 | F45: =COUNTIF(TI!$DC32:$EF32,"=4") -> 0 | G45: =COUNTIF(TI!$DC32:$EF32,"=5") -> 0 | H45: {=IF(SUM(C45:G45)=0,,SUM((C45:G45)*($C$18:$G$18))/SUM(C45:G45))} -> 0
B46: 4 | C46: =COUNTIF(TI!$DC33:$EF33,"=1") -> 0 | D46: =COUNTIF(TI!$DC33:$EF33,"=2") -> 0 | E46: =COUNTIF(TI!$DC33:$EF33,"=3") -> 0 | F46: =COUNTIF(TI!$DC33:$EF33,"=4") -> 0 | G46: =COUNTIF(TI!$DC33:$EF33,"=5") -> 0 | H46: {=IF(SUM(C46:G46)=0,,SUM((C46:G46)*($C$18:$G$18))/SUM(C46:G46))} -> 0
B47: 5 | C47: =COUNTIF(TI!$DC34:$EF34,"=1") -> 0 | D47: =COUNTIF(TI!$DC34:$EF34,"=2") -> 0 | E47: =COUNTIF(TI!$DC34:$EF34,"=3") -> 0 | F47: =COUNTIF(TI!$DC34:$EF34,"=4") -> 0 | G47: =COUNTIF(TI!$DC34:$EF34,"=5") -> 0 | H47: {=IF(SUM(C47:G47)=0,,SUM((C47:G47)*($C$18:$G$18))/SUM(C47:G47))} -> 0
B48: TOTAL AREA RATING | C48: =SUM(C43:C47)*C$18 -> 0 | D48: =SUM(D43:D47)*D$18 -> 0 | E48: =SUM(E43:E47)*E$18 -> 0 | F48: =SUM(F43:F47)*F$18 -> 0 | G48: =SUM(G43:G47)*G$18 -> 0 | H48: =SUM(H43:H47)*4 -> 0
F54: =TI!DZ75 -> DANIEL E. MALIGAT, JR., DIT
...

Sheet 02A-P
B1: NBC 461- QCE FORM 02A
B4: CAMARINES NORTE STATE COLLEGE
B5: Daet, Camarines Norte
B7: SECTORAL FREQUENCY OF RATING PER AREA
B8: FOR INSTRUCTORS AND ASSISTANT PROFESSORS
C9: SECTORAL EVALUATOR | E9: PEERS
B12: NAME OF FACULTY | C12: =TI!DC6 -> ,
B13: RATING PERIOD | C13: =TI!MG6 -> 0
B15: INSTRUCTION
B16: I. COMMITMENT
B17: CRITERIA | C17: RATING SCALE (1-Lowest, 5-Highest) | H17: AVERAGE
B18: NUMBER | C18: 1 | D18: 2 | E18: 3 | F18: 4 | G18: 5 | H18: RATING
B19: 1 | C19: =COUNTIF(TI!$MG12:$MP12,"=1") -> 0 | D19: =COUNTIF(TI!$MG12:$MP12,"=2") -> 0 | E19: =COUNTIF(TI!$MG12:$MP12,"=3") -> 0 | F19: =COUNTIF(TI!$MG12:$MP12,"=4") -> 0 | G19: =COUNTIF(TI!$MG12:$MP12,"=5") -> 0 | H19: {=IF(SUM(C19:G19)=0,,SUM((C19:G19)*($C$18:$G$18))/SUM(C19:G19))} -> 0
B20: 2 | C20: =COUNTIF(TI!$MG13:$MP13,"=1") -> 0 | D20: =COUNTIF(TI!$MG13:$MP13,"=2") -> 0 | E20: =COUNTIF(TI!$MG13:$MP13,"=3") -> 0 | F20: =COUNTIF(TI!$MG13:$MP13,"=4") -> 0 | G20: =COUNTIF(TI!$MG13:$MP13,"=5") -> 0 | H20: {=IF(SUM(C20:G20)=0,,SUM((C20:G20)*($C$18:$G$18))/SUM(C20:G20))} -> 0
B21: 3 | C21: =COUNTIF(TI!$MG14:$MP14,"=1") -> 0 | D21: =COUNTIF(TI!$MG14:$MP14,"=2") -> 0 | E21: =COUNTIF(TI!$MG14:$MP14,"=3") -> 0 | F21: =COUNTIF(TI!$MG14:$MP14,"=4") -> 0 | G21: =COUNTIF(TI!$MG14:$MP14,"=5") -> 0 | H21: {=IF(SUM(C21:G21)=0,,SUM((C21:G21)*($C$18:$G$18))/SUM(C21:G21))} -> 0
B22: 4 | C22: =COUNTIF(TI!$MG15:$MP15,"=1") -> 0 | D22: =COUNTIF(TI!$MG15:$MP15,"=2") -> 0 | E22: =COUNTIF(TI!$MG15:$MP15,"=3") -> 0 | F22: =COUNTIF(TI!$MG15:$MP15,"=4") -> 0 | G22: =COUNTIF(TI!$MG15:$MP15,"=5") -> 0 | H22: {=IF(SUM(C22:G22)=0,,SUM((C22:G22)*($C$18:$G$18))/SUM(C22:G22))} -> 0
B23: 5 | C23: =COUNTIF(TI!$MG16:$MP16,"=1") -> 0 | D23: =COUNTIF(TI!$MG16:$MP16,"=2") -> 0 | E23: =COUNTIF(TI!$MG16:$MP16,"=3") -> 0 | F23: =COUNTIF(TI!$MG16:$MP16,"=4") -> 0 | G23: =COUNTIF(TI!$MG16:$MP16,"=5") -> 0 | H23: {=IF(SUM(C23:G23)=0,,SUM((C23:G23)*($C$18:$G$18))/SUM(C23:G23))} -> 0
B24: TOTAL AREA RATING | C24: =SUM(C19:C23)*C$18 -> 0 | D24: =SUM(D19:D23)*D$18 -> 0 | E24: =SUM(E19:E23)*E$18 -> 0 | F24: =SUM(F19:F23)*F$18 -> 0 | G24: =SUM(G19:G23)*G$18 -> 0 | H24: =SUM(H19:H23)*4 -> 0
B26: II. KNOWLEDGE OF SUBJECT
B27: 1 | C27: =COUNTIF(TI!$MG18:$MP18,"=1") -> 0 | D27: =COUNTIF(TI!$MG18:$MP18,"=2") -> 0 | E27: =COUNTIF(TI!$MG18:$MP18,"=3") -> 0 | F27: =COUNTIF(TI!$MG18:$MP18,"=4") -> 0 | G27: =COUNTIF(TI!$MG18:$MP18,"=5") -> 0 | H27: {=IF(SUM(C27:G27)=0,,SUM((C27:G27)*($C$18:$G$18))/SUM(C27:G27))} -> 0
B28: 2 | C28: =COUNTIF(TI!$MG19:$MP19,"=1") -> 0 | D28: =COUNTIF(TI!$MG19:$MP19,"=2") -> 0 | E28: =COUNTIF(TI!$MG19:$MP19,"=3") -> 0 | F28: =COUNTIF(TI!$MG19:$MP19,"=4") -> 0 | G28: =COUNTIF(TI!$MG19:$MP19,"=5") -> 0 | H28: {=IF(SUM(C28:G28)=0,,SUM((C28:G28)*($C$18:$G$18))/SUM(C28:G28))} -> 0
B29: 3 | C29: =COUNTIF(TI!$MG20:$MP20,"=1") -> 0 | D29: =COUNTIF(TI!$MG20:$MP20,"=2") -> 0 | E29: =COUNTIF(TI!$MG20:$MP20,"=3") -> 0 | F29: =COUNTIF(TI!$MG20:$MP20,"=4") -> 0 | G29: =COUNTIF(TI!$MG20:$MP20,"=5") -> 0 | H29: {=IF(SUM(C29:G29)=0,,SUM((C29:G29)*($C$18:$G$18))/SUM(C29:G29))} -> 0
B30: 4 | C30: =COUNTIF(TI!$MG21:$MP21,"=1") -> 0 | D30: =COUNTIF(TI!$MG21:$MP21,"=2") -> 0 | E30: =COUNTIF(TI!$MG21:$MP21,"=3") -> 0 | F30: =COUNTIF(TI!$MG21:$MP21,"=4") -> 0 | G30: =COUNTIF(TI!$MG21:$MP21,"=5") -> 0 | H30: {=IF(SUM(C30:G30)=0,,SUM((C30:G30)*($C$18:$G$18))/SUM(C30:G30))} -> 0
B31: 5 | C31: =COUNTIF(TI!$MG22:$MP22,"=1") -> 0 | D31: =COUNTIF(TI!$MG22:$MP22,"=2") -> 0 | E31: =COUNTIF(TI!$MG22:$MP22,"=3") -> 0 | F31: =COUNTIF(TI!$MG22:$MP22,"=4") -> 0 | G31: =COUNTIF(TI!$MG22:$MP22,"=5") -> 0 | H31: {=IF(SUM(C31:G31)=0,,SUM((C31:G31)*($C$18:$G$18))/SUM(C31:G31))} -> 0
B32: TOTAL AREA RATING | C32: =SUM(C27:C31)*C$18 -> 0 | D32: =SUM(D27:D31)*D$18 -> 0 | E32: =SUM(E27:E31)*E$18 -> 0 | F32: =SUM(F27:F31)*F$18 -> 0 | G32: =SUM(G27:G31)*G$18 -> 0 | H32: =SUM(H27:H31)*4 -> 0
B34: III. TEACHING FOR INDEPENDENT LEARNING
B35: 1 | C35: =COUNTIF(TI!$MG24:$MP24,"=1") -> 0 | D35: =COUNTIF(TI!$MG24:$MP24,"=2") -> 0 | E35: =COUNTIF(TI!$MG24:$MP24,"=3") -> 0 | F35: =COUNTIF(TI!$MG24:$MP24,"=4") -> 0 | G35: =COUNTIF(TI!$MG24:$MP24,"=5") -> 0 | H35: {=IF(SUM(C35:G35)=0,,SUM((C35:G35)*($C$18:$G$18))/SUM(C35:G35))} -> 0
B36: 2 | C36: =COUNTIF(TI!$MG25:$MP25,"=1") -> 0 | D36: =COUNTIF(TI!$MG25:$MP25,"=2") -> 0 | E36: =COUNTIF(TI!$MG25:$MP25,"=3") -> 0 | F36: =COUNTIF(TI!$MG25:$MP25,"=4") -> 0 | G36: =COUNTIF(TI!$MG25:$MP25,"=5") -> 0 | H36: {=IF(SUM(C36:G36)=0,,SUM((C36:G36)*($C$18:$G$18))/SUM(C36:G36))} -> 0
B37: 3 | C37: =COUNTIF(TI!$MG26:$MP26,"=1") -> 0 | D37: =COUNTIF(TI!$MG26:$MP26,"=2") -> 0 | E37: =COUNTIF(TI!$MG26:$MP26,"=3") -> 0 | F37: =COUNTIF(TI!$MG26:$MP26,"=4") -> 0 | G37: =COUNTIF(TI!$MG26:$MP26,"=5") -> 0 | H37: {=IF(SUM(C37:G37)=0,,SUM((C37:G37)*($C$18:$G$18))/SUM(C37:G37))} -> 0
B38: 4 | C38: =COUNTIF(TI!$MG27:$MP27,"=1") -> 0 | D38: =COUNTIF(TI!$MG27:$MP27,"=2") -> 0 | E38: =COUNTIF(TI!$MG27:$MP27,"=3") -> 0 | F38: =COUNTIF(TI!$MG27:$MP27,"=4") -> 0 | G38: =COUNTIF(TI!$MG27:$MP27,"=5") -> 0 | H38: {=IF(SUM(C38:G38)=0,,SUM((C38:G38)*($C$18:$G$18))/SUM(C38:G38))} -> 0
B39: 5 | C39: =COUNTIF(TI!$MG28:$MP28,"=1") -> 0 | D39: =COUNTIF(TI!$MG28:$MP28,"=2") -> 0 | E39: =COUNTIF(TI!$MG28:$MP28,"=3") -> 0 | F39: =COUNTIF(TI!$MG28:$MP28,"=4") -> 0 | G39: =COUNTIF(TI!$MG28:$MP28,"=5") -> 0 | H39: {=IF(SUM(C39:G39)=0,,SUM((C39:G39)*($C$18:$G$18))/SUM(C39:G39))} -> 0
B40: TOTAL AREA RATING | C40: =SUM(C35:C39)*C$18 -> 0 | D40: =SUM(D35:D39)*D$18 -> 0 | E40: =SUM(E35:E39)*E$18 -> 0 | F40: =SUM(F35:F39)*F$18 -> 0 | G40: =SUM(G35:G39)*G$18 -> 0 | H40: =SUM(H35:H39)*4 -> 0
B42: IV. MANAGEMENT OF LEARNING
B43: 1 | C43: =COUNTIF(TI!$MG30:$MP30,"=1") -> 0 | D43: =COUNTIF(TI!$MG30:$MP30,"=2") -> 0 | E43: =COUNTIF(TI!$MG30:$MP30,"=3") -> 0 | F43: =COUNTIF(TI!$MG30:$MP30,"=4") -> 0 | G43: =COUNTIF(TI!$MG30:$MP30,"=5") -> 0 | H43: {=IF(SUM(C43:G43)=0,,SUM((C43:G43)*($C$18:$G$18))/SUM(C43:G43))} -> 0
B44: 2 | C44: =COUNTIF(TI!$MG31:$MP31,"=1") -> 0 | D44: =COUNTIF(TI!$MG31:$MP31,"=2") -> 0 | E44: =COUNTIF(TI!$MG31:$MP31,"=3") -> 0 | F44: =COUNTIF(TI!$MG31:$MP31,"=4") -> 0 | G44: =COUNTIF(TI!$MG31:$MP31,"=5") -> 0 | H44: {=IF(SUM(C44:G44)=0,,SUM((C44:G44)*($C$18:$G$18))/SUM(C44:G44))} -> 0
B45: 3 | C45: =COUNTIF(TI!$MG32:$MP32,"=1") -> 0 | D45: =COUNTIF(TI!$MG32:$MP32,"=2") -> 0 | E45: =COUNTIF(TI!$MG32:$MP32,"=3") -> 0 | F45: =COUNTIF(TI!$MG32:$MP32,"=4") -> 0 | G45: =COUNTIF(TI!$MG32:$MP32,"=5") -> 0 | H45: {=IF(SUM(C45:G45)=0,,SUM((C45:G45)*($C$18:$G$18))/SUM(C45:G45))} -> 0
B46: 4 | C46: =COUNTIF(TI!$MG33:$MP33,"=1") -> 0 | D46: =COUNTIF(TI!$MG33:$MP33,"=2") -> 0 | E46: =COUNTIF(TI!$MG33:$MP33,"=3") -> 0 | F46: =COUNTIF(TI!$MG33:$MP33,"=4") -> 0 | G46: =COUNTIF(TI!$MG33:$MP33,"=5") -> 0 | H46: {=IF(SUM(C46:G46)=0,,SUM((C46:G46)*($C$18:$G$18))/SUM(C46:G46))} -> 0
B47: 5 | C47: =COUNTIF(TI!$MG34:$MP34,"=1") -> 0 | D47: =COUNTIF(TI!$MG34:$MP34,"=2") -> 0 | E47: =COUNTIF(TI!$MG34:$MP34,"=3") -> 0 | F47: =COUNTIF(TI!$MG34:$MP34,"=4") -> 0 | G47: =COUNTIF(TI!$MG34:$MP34,"=5") -> 0 | H47: {=IF(SUM(C47:G47)=0,,SUM((C47:G47)*($C$18:$G$18))/SUM(C47:G47))} -> 0
B48: TOTAL AREA RATING | C48: =SUM(C43:C47)*C$18 -> 0 | D48: =SUM(D43:D47)*D$18 -> 0 | E48: =SUM(E43:E47)*E$18 -> 0 | F48: =SUM(F43:F47)*F$18 -> 0 | G48: =SUM(G43:G47)*G$18 -> 0 | H48: =SUM(H43:H47)*4 -> 0
F54: =TI!DZ75 -> DANIEL E. MALIGAT, JR., DIT
...

Sheet 02B-Res
B1: NBC 461- QCE FORM 02B
B4: CAMARINES NORTE STATE COLLEGE
B5: Daet, Camarines Norte
B7: SECTORAL FREQUENCY OF RATING PER AREA
B8: FOR ASSOCIATE PROFESSORS AND FULL PROFESSORS
C9: SECTORAL EVALUATOR
B12: NAME OF FACULTY | C12: =TI!DC6 -> ,
B13: RATING PERIOD | C13: =TI!MG6 -> 0
B15: RESEARCH
B16: I. CLIENTELE SATISFACTION | D16: =TR!J9 -> 0.2
B17: CRITERIA | C17: RATING SCALE (1-Lowest, 5-Highest) | H17: AVERAGE
B18: NUMBER | C18: 1 | D18: 2 | E18: 3 | F18: 4 | G18: 5 | H18: RATING
B19: 1 | C19: =COUNTIF(TR!$E12:$BB12,"=1")+COUNTIF(TR!$E19:$BB19,"=1")+COUNTIF(TR!$E26:$BB26,"=1")+COUNTIF(TR!$E33:$BB33,"=1") -> 0 | D19: =COUNTIF(TR!$E12:$BB12,"=2")+COUNTIF(TR!$E19:$BB19,"=2")+COUNTIF(TR!$E26:$BB26,"=2")+COUNTIF(TR!$E33:$BB33,"=2") -> 0 | E19: =COUNTIF(TR!$E12:$BB12,"=3")+COUNTIF(TR!$E19:$BB19,"=3")+COUNTIF(TR!$E26:$BB26,"=3")+COUNTIF(TR!$E33:$BB33,"=3") -> 0 | F19: =COUNTIF(TR!$E12:$BB12,"=4")+COUNTIF(TR!$E19:$BB19,"=4")+COUNTIF(TR!$E26:$BB26,"=4")+COUNTIF(TR!$E33:$BB33,"=4") -> 0 | G19: =COUNTIF(TR!$E12:$BB12,"=5")+COUNTIF(TR!$E19:$BB19,"=5")+COUNTIF(TR!$E26:$BB26,"=5")+COUNTIF(TR!$E33:$BB33,"=5") -> 0 | H19: {=IF(SUM(C19:G19)=0,,SUM((C19:G19)*($C$18:$G$18))/SUM(C19:G19))} -> 0
B20: 2 | C20: =COUNTIF(TR!$E13:$BB13,"=1")+COUNTIF(TR!$E20:$BB20,"=1")+COUNTIF(TR!$E27:$BB27,"=1")+COUNTIF(TR!$E34:$BB34,"=1") -> 0 | D20: =COUNTIF(TR!$E13:$BB13,"=2")+COUNTIF(TR!$E20:$BB20,"=2")+COUNTIF(TR!$E27:$BB27,"=2")+COUNTIF(TR!$E34:$BB34,"=2") -> 0 | E20: =COUNTIF(TR!$E13:$BB13,"=3")+COUNTIF(TR!$E20:$BB20,"=3")+COUNTIF(TR!$E27:$BB27,"=3")+COUNTIF(TR!$E34:$BB34,"=3") -> 0 | F20: =COUNTIF(TR!$E13:$BB13,"=4")+COUNTIF(TR!$E20:$BB20,"=4")+COUNTIF(TR!$E27:$BB27,"=4")+COUNTIF(TR!$E34:$BB34,"=4") -> 0 | G20: =COUNTIF(TR!$E13:$BB13,"=5")+COUNTIF(TR!$E20:$BB20,"=5")+COUNTIF(TR!$E27:$BB27,"=5")+COUNTIF(TR!$E34:$BB34,"=5") -> 0 | H20: {=IF(SUM(C20:G20)=0,,SUM((C20:G20)*($C$18:$G$18))/SUM(C20:G20))} -> 0
B21: 3 | C21: =COUNTIF(TR!$E14:$BB14,"=1")+COUNTIF(TR!$E21:$BB21,"=1")+COUNTIF(TR!$E28:$BB28,"=1")+COUNTIF(TR!$E35:$BB35,"=1") -> 0 | D21: =COUNTIF(TR!$E14:$BB14,"=2")+COUNTIF(TR!$E21:$BB21,"=2")+COUNTIF(TR!$E28:$BB28,"=2")+COUNTIF(TR!$E35:$BB35,"=2") -> 0 | E21: =COUNTIF(TR!$E14:$BB14,"=3")+COUNTIF(TR!$E21:$BB21,"=3")+COUNTIF(TR!$E28:$BB28,"=3")+COUNTIF(TR!$E35:$BB35,"=3") -> 0 | F21: =COUNTIF(TR!$E14:$BB14,"=4")+COUNTIF(TR!$E21:$BB21,"=4")+COUNTIF(TR!$E28:$BB28,"=4")+COUNTIF(TR!$E35:$BB35,"=4") -> 0 | G21: =COUNTIF(TR!$E14:$BB14,"=5")+COUNTIF(TR!$E21:$BB21,"=5")+COUNTIF(TR!$E28:$BB28,"=5")+COUNTIF(TR!$E35:$BB35,"=5") -> 0 | H21: {=IF(SUM(C21:G21)=0,,SUM((C21:G21)*($C$18:$G$18))/SUM(C21:G21))} -> 0
B22: 4 | C22: =COUNTIF(TR!$E15:$BB15,"=1")+COUNTIF(TR!$E22:$BB22,"=1")+COUNTIF(TR!$E29:$BB29,"=1")+COUNTIF(TR!$E36:$BB36,"=1") -> 0 | D22: =COUNTIF(TR!$E15:$BB15,"=2")+COUNTIF(TR!$E22:$BB22,"=2")+COUNTIF(TR!$E29:$BB29,"=2")+COUNTIF(TR!$E36:$BB36,"=2") -> 0 | E22: =COUNTIF(TR!$E15:$BB15,"=3")+COUNTIF(TR!$E22:$BB22,"=3")+COUNTIF(TR!$E29:$BB29,"=3")+COUNTIF(TR!$E36:$BB36,"=3") -> 0 | F22: =COUNTIF(TR!$E15:$BB15,"=4")+COUNTIF(TR!$E22:$BB22,"=4")+COUNTIF(TR!$E29:$BB29,"=4")+COUNTIF(TR!$E36:$BB36,"=4") -> 0 | G22: =COUNTIF(TR!$E15:$BB15,"=5")+COUNTIF(TR!$E22:$BB22,"=5")+COUNTIF(TR!$E29:$BB29,"=5")+COUNTIF(TR!$E36:$BB36,"=5") -> 0 | H22: {=IF(SUM(C22:G22)=0,,SUM((C22:G22)*($C$18:$G$18))/SUM(C22:G22))} -> 0
B23: 5 | C23: =COUNTIF(TR!$E16:$BB16,"=1")+COUNTIF(TR!$E23:$BB23,"=1")+COUNTIF(TR!$E30:$BB30,"=1")+COUNTIF(TR!$E37:$BB37,"=1") -> 0 | D23: =COUNTIF(TR!$E16:$BB16,"=2")+COUNTIF(TR!$E23:$BB23,"=2")+COUNTIF(TR!$E30:$BB30,"=2")+COUNTIF(TR!$E37:$BB37,"=2") -> 0 | E23: =COUNTIF(TR!$E16:$BB16,"=3")+COUNTIF(TR!$E23:$BB23,"=3")+COUNTIF(TR!$E30:$BB30,"=3")+COUNTIF(TR!$E37:$BB37,"=3") -> 0 | F23: =COUNTIF(TR!$E16:$BB16,"=4")+COUNTIF(TR!$E23:$BB23,"=4")+COUNTIF(TR!$E30:$BB30,"=4")+COUNTIF(TR!$E37:$BB37,"=4") -> 0 | G23: =COUNTIF(TR!$E16:$BB16,"=5")+COUNTIF(TR!$E23:$BB23,"=5")+COUNTIF(TR!$E30:$BB30,"=5")+COUNTIF(TR!$E37:$BB37,"=5") -> 0 | H23: {=IF(SUM(C23:G23)=0,,SUM((C23:G23)*($C$18:$G$18))/SUM(C23:G23))} -> 0
B24: TOTAL AREA RATING | C24: =SUM(C19:C23)*C$18 -> 0 | D24: =SUM(D19:D23)*D$18 -> 0 | E24: =SUM(E19:E23)*E$18 -> 0 | F24: =SUM(F19:F23)*F$18 -> 0 | G24: =SUM(G19:G23)*G$18 -> 0 | H24: =SUM(H19:H23)*4 -> 0
B26: II. LEADERSHIP | D26: =TR!E41 -> 0.2
B27: 1 | C27: =COUNTIF(TR!$C43,"=1") -> 0 | D27: =COUNTIF(TR!$C43,"=2") -> 0 | E27: =COUNTIF(TR!$C43,"=3") -> 0 | F27: =COUNTIF(TR!$C43,"=4") -> 0 | G27: =COUNTIF(TR!$C43,"=5") -> 0 | H27: {=IF(SUM(C27:G27)=0,,SUM((C27:G27)*($C$18:$G$18))/SUM(C27:G27))} -> 0
B28: 2 | C28: =COUNTIF(TR!$C44,"=1") -> 0 | D28: =COUNTIF(TR!$C44,"=2") -> 0 | E28: =COUNTIF(TR!$C44,"=3") -> 0 | F28: =COUNTIF(TR!$C44,"=4") -> 0 | G28: =COUNTIF(TR!$C44,"=5") -> 0 | H28: {=IF(SUM(C28:G28)=0,,SUM((C28:G28)*($C$18:$G$18))/SUM(C28:G28))} -> 0
B29: 3 | C29: =COUNTIF(TR!$C45,"=1") -> 0 | D29: =COUNTIF(TR!$C45,"=2") -> 0 | E29: =COUNTIF(TR!$C45,"=3") -> 0 | F29: =COUNTIF(TR!$C45,"=4") -> 0 | G29: =COUNTIF(TR!$C45,"=5") -> 0 | H29: {=IF(SUM(C29:G29)=0,,SUM((C29:G29)*($C$18:$G$18))/SUM(C29:G29))} -> 0
B30: 4 | C30: =COUNTIF(TR!$C46,"=1") -> 0 | D30: =COUNTIF(TR!$C46,"=2") -> 0 | E30: =COUNTIF(TR!$C46,"=3") -> 0 | F30: =COUNTIF(TR!$C46,"=4") -> 0 | G30: =COUNTIF(TR!$C46,"=5") -> 0 | H30: {=IF(SUM(C30:G30)=0,,SUM((C30:G30)*($C$18:$G$18))/SUM(C30:G30))} -> 0
B31: 5 | C31: =COUNTIF(TR!$C47,"=1") -> 0 | D31: =COUNTIF(TR!$C47,"=2") -> 0 | E31: =COUNTIF(TR!$C47,"=3") -> 0 | F31: =COUNTIF(TR!$C47,"=4") -> 0 | G31: =COUNTIF(TR!$C47,"=5") -> 0 | H31: {=IF(SUM(C31:G31)=0,,SUM((C31:G31)*($C$18:$G$18))/SUM(C31:G31))} -> 0
B32: TOTAL AREA RATING | C32: =SUM(C27:C31)*C$18 -> 0 | D32: =SUM(D27:D31)*D$18 -> 0 | E32: =SUM(E27:E31)*E$18 -> 0 | F32: =SUM(F27:F31)*F$18 -> 0 | G32: =SUM(G27:G31)*G$18 -> 0 | H32: =SUM(H27:H31)*4 -> 0
B34: III. PARTNERSHIP DEVELOPMENT | D34: =TR!O41 -> 0.3
B35: 1 | C35: =COUNTIF(TR!$K43:$Q43,"=1") -> 0 | D35: =COUNTIF(TR!$K43:$Q43,"=2") -> 0 | E35: =COUNTIF(TR!$K43:$Q43,"=3") -> 0 | F35: =COUNTIF(TR!$K43:$Q43,"=4") -> 0 | G35: =COUNTIF(TR!$K43:$Q43,"=5") -> 0 | H35: {=IF(SUM(C35:G35)=0,,SUM((C35:G35)*($C$18:$G$18))/SUM(C35:G35))} -> 0
B36: 2 | C36: =COUNTIF(TR!$K44:$Q44,"=1") -> 0 | D36: =COUNTIF(TR!$K44:$Q44,"=2") -> 0 | E36: =COUNTIF(TR!$K44:$Q44,"=3") -> 0 | F36: =COUNTIF(TR!$K44:$Q44,"=4") -> 0 | G36: =COUNTIF(TR!$K44:$Q44,"=5") -> 0 | H36: {=IF(SUM(C36:G36)=0,,SUM((C36:G36)*($C$18:$G$18))/SUM(C36:G36))} -> 0
B37: 3 | C37: =COUNTIF(TR!$K45:$Q45,"=1") -> 0 | D37: =COUNTIF(TR!$K45:$Q45,"=2") -> 0 | E37: =COUNTIF(TR!$K45:$Q45,"=3") -> 0 | F37: =COUNTIF(TR!$K45:$Q45,"=4") -> 0 | G37: =COUNTIF(TR!$K45:$Q45,"=5") -> 0 | H37: {=IF(SUM(C37:G37)=0,,SUM((C37:G37)*($C$18:$G$18))/SUM(C37:G37))} -> 0
B38: 4 | C38: =COUNTIF(TR!$K46:$Q46,"=1") -> 0 | D38: =COUNTIF(TR!$K46:$Q46,"=2") -> 0 | E38: =COUNTIF(TR!$K46:$Q46,"=3") -> 0 | F38: =COUNTIF(TR!$K46:$Q46,"=4") -> 0 | G38: =COUNTIF(TR!$K46:$Q46,"=5") -> 0 | H38: {=IF(SUM(C38:G38)=0,,SUM((C38:G38)*($C$18:$G$18))/SUM(C38:G38))} -> 0
B39: 5 | C39: =COUNTIF(TR!$K47:$Q47,"=1") -> 0 | D39: =COUNTIF(TR!$K47:$Q47,"=2") -> 0 | E39: =COUNTIF(TR!$K47:$Q47,"=3") -> 0 | F39: =COUNTIF(TR!$K47:$Q47,"=4") -> 0 | G39: =COUNTIF(TR!$K47:$Q47,"=5") -> 0 | H39: {=IF(SUM(C39:G39)=0,,SUM((C39:G39)*($C$18:$G$18))/SUM(C39:G39))} -> 0
B40: TOTAL AREA RATING | C40: =SUM(C35:C39)*C$18 -> 0 | D40: =SUM(D35:D39)*D$18 -> 0 | E40: =SUM(E35:E39)*E$18 -> 0 | F40: =SUM(F35:F39)*F$18 -> 0 | G40: =SUM(G35:G39)*G$18 -> 0 | H40: =SUM(H35:H39)*4 -> 0
B42: IV. COMMUNITY RESPONSIBILITY | D42: =TR!AC40 -> 0.3
B43: 1 | C43: =COUNTIF(TR!$U43:$AF43,"=1") -> 0 | D43: =COUNTIF(TR!$U43:$AF43,"=2") -> 0 | E43: =COUNTIF(TR!$U43:$AF43,"=3") -> 0 | F43: =COUNTIF(TR!$U43:$AF43,"=4") -> 0 | G43: =COUNTIF(TR!$U43:$AF43,"=5") -> 0 | H43: {=IF(SUM(C43:G43)=0,,SUM((C43:G43)*($C$18:$G$18))/SUM(C43:G43))} -> 0
B44: 2 | C44: =COUNTIF(TR!$U44:$AF44,"=1") -> 0 | D44: =COUNTIF(TR!$U44:$AF44,"=2") -> 0 | E44: =COUNTIF(TR!$U44:$AF44,"=3") -> 0 | F44: =COUNTIF(TR!$U44:$AF44,"=4") -> 0 | G44: =COUNTIF(TR!$U44:$AF44,"=5") -> 0 | H44: {=IF(SUM(C44:G44)=0,,SUM((C44:G44)*($C$18:$G$18))/SUM(C44:G44))} -> 0
B45: 3 | C45: =COUNTIF(TR!$U45:$AF45,"=1") -> 0 | D45: =COUNTIF(TR!$U45:$AF45,"=2") -> 0 | E45: =COUNTIF(TR!$U45:$AF45,"=3") -> 0 | F45: =COUNTIF(TR!$U45:$AF45,"=4") -> 0 | G45: =COUNTIF(TR!$U45:$AF45,"=5") -> 0 | H45: {=IF(SUM(C45:G45)=0,,SUM((C45:G45)*($C$18:$G$18))/SUM(C45:G45))} -> 0
B46: 4 | C46: =COUNTIF(TR!$U46:$AF46,"=1") -> 0 | D46: =COUNTIF(TR!$U46:$AF46,"=2") -> 0 | E46: =COUNTIF(TR!$U46:$AF46,"=3") -> 0 | F46: =COUNTIF(TR!$U46:$AF46,"=4") -> 0 | G46: =COUNTIF(TR!$U46:$AF46,"=5") -> 0 | H46: {=IF(SUM(C46:G46)=0,,SUM((C46:G46)*($C$18:$G$18))/SUM(C46:G46))} -> 0
B47: 5 | C47: =COUNTIF(TR!$U47:$AF47,"=1") -> 0 | D47: =COUNTIF(TR!$U47:$AF47,"=2") -> 0 | E47: =COUNTIF(TR!$U47:$AF47,"=3") -> 0 | F47: =COUNTIF(TR!$U47:$AF47,"=4") -> 0 | G47: =COUNTIF(TR!$U47:$AF47,"=5") -> 0 | H47: {=IF(SUM(C47:G47)=0,,SUM((C47:G47)*($C$18:$G$18))/SUM(C47:G47))} -> 0
B48: TOTAL AREA RATING | C48: =SUM(C43:C47)*C$18 -> 0 | D48: =SUM(D43:D47)*D$18 -> 0 | E48: =SUM(E43:E47)*E$18 -> 0 | F48: =SUM(F43:F47)*F$18 -> 0 | G48: =SUM(G43:G47)*G$18 -> 0 | H48: =SUM(H43:H47)*4 -> 0
F54: =TI!DZ75 -> DANIEL E. MALIGAT, JR., DIT
...

Sheet 02B-Ext
B1: NBC 461- QCE FORM 02B
B4: CAMARINES NORTE STATE COLLEGE
B5: Daet, Camarines Norte
B7: SECTORAL FREQUENCY OF RATING PER AREA
B8: FOR ASSOCIATE PROFESSORS AND FULL PROFESSORS
C9: SECTORAL EVALUATOR
B12: NAME OF FACULTY | C12: =TI!DC6 -> ,
B13: RATING PERIOD | C13: =TI!MG6 -> 0
B15: EXTENSION
B16: I. CLIENTELE SATISFACTION | D16: =TE!J9 -> 0.2
B17: CRITERIA | C17: RATING SCALE (1-Lowest, 5-Highest) | H17: AVERAGE
B18: NUMBER | C18: 1 | D18: 2 | E18: 3 | F18: 4 | G18: 5 | H18: RATING
B19: 1 | C19: =COUNTIF(TE!$E12:$BB12,"=1")+COUNTIF(TE!$E19:$BB19,"=1")+COUNTIF(TE!$E26:$BB26,"=1")+COUNTIF(TE!$E33:$BB33,"=1") -> 0 | D19: =COUNTIF(TE!$E12:$BB12,"=2")+COUNTIF(TE!$E19:$BB19,"=2")+COUNTIF(TE!$E26:$BB26,"=2")+COUNTIF(TE!$E33:$BB33,"=2") -> 0 | E19: =COUNTIF(TE!$E12:$BB12,"=3")+COUNTIF(TE!$E19:$BB19,"=3")+COUNTIF(TE!$E26:$BB26,"=3")+COUNTIF(TE!$E33:$BB33,"=3") -> 0 | F19: =COUNTIF(TE!$E12:$BB12,"=4")+COUNTIF(TE!$E19:$BB19,"=4")+COUNTIF(TE!$E26:$BB26,"=4")+COUNTIF(TE!$E33:$BB33,"=4") -> 0 | G19: =COUNTIF(TE!$E12:$BB12,"=5")+COUNTIF(TE!$E19:$BB19,"=5")+COUNTIF(TE!$E26:$BB26,"=5")+COUNTIF(TE!$E33:$BB33,"=5") -> 0 | H19: {=IF(SUM(C19:G19)=0,,SUM((C19:G19)*($C$18:$G$18))/SUM(C19:G19))} -> 0
B20: 2 | C20: =COUNTIF(TE!$E13:$BB13,"=1")+COUNTIF(TE!$E20:$BB20,"=1")+COUNTIF(TE!$E27:$BB27,"=1")+COUNTIF(TE!$E34:$BB34,"=1") -> 0 | D20: =COUNTIF(TE!$E13:$BB13,"=2")+COUNTIF(TE!$E20:$BB20,"=2")+COUNTIF(TE!$E27:$BB27,"=2")+COUNTIF(TE!$E34:$BB34,"=2") -> 0 | E20: =COUNTIF(TE!$E13:$BB13,"=3")+COUNTIF(TE!$E20:$BB20,"=3")+COUNTIF(TE!$E27:$BB27,"=3")+COUNTIF(TE!$E34:$BB34,"=3") -> 0 | F20: =COUNTIF(TE!$E13:$BB13,"=4")+COUNTIF(TE!$E20:$BB20,"=4")+COUNTIF(TE!$E27:$BB27,"=4")+COUNTIF(TE!$E34:$BB34,"=4") -> 0 | G20: =COUNTIF(TE!$E13:$BB13,"=5")+COUNTIF(TE!$E20:$BB20,"=5")+COUNTIF(TE!$E27:$BB27,"=5")+COUNTIF(TE!$E34:$BB34,"=5") -> 0 | H20: {=IF(SUM(C20:G20)=0,,SUM((C20:G20)*($C$18:$G$18))/SUM(C20:G20))} -> 0
B21: 3 | C21: =COUNTIF(TE!$E14:$BB14,"=1")+COUNTIF(TE!$E21:$BB21,"=1")+COUNTIF(TE!$E28:$BB28,"=1")+COUNTIF(TE!$E35:$BB35,"=1") -> 0 | D21: =COUNTIF(TE!$E14:$BB14,"=2")+COUNTIF(TE!$E21:$BB21,"=2")+COUNTIF(TE!$E28:$BB28,"=2")+COUNTIF(TE!$E35:$BB35,"=2") -> 0 | E21: =COUNTIF(TE!$E14:$BB14,"=3")+COUNTIF(TE!$E21:$BB21,"=3")+COUNTIF(TE!$E28:$BB28,"=3")+COUNTIF(TE!$E35:$BB35,"=3") -> 0 | F21: =COUNTIF(TE!$E14:$BB14,"=4")+COUNTIF(TE!$E21:$BB21,"=4")+COUNTIF(TE!$E28:$BB28,"=4")+COUNTIF(TE!$E35:$BB35,"=4") -> 0 | G21: =COUNTIF(TE!$E14:$BB14,"=5")+COUNTIF(TE!$E21:$BB21,"=5")+COUNTIF(TE!$E28:$BB28,"=5")+COUNTIF(TE!$E35:$BB35,"=5") -> 0 | H21: {=IF(SUM(C21:G21)=0,,SUM((C21:G21)*($C$18:$G$18))/SUM(C21:G21))} -> 0
